Workbook

Sheet Important Matters
A1: 2012-2013 第一學期考試 | G1: 41190
A2: 1. 監考時數
A3: (A) | B3: 教師(除T36, T43, T61 及負責 SEN 的老師 T25, T114, T140)
B4: 平均約 11.12 小時(已包括去年的偏差)
B5: T25, T114, T140 因要負責監考 SEN 的同學，而SEN監考考試時間未能趕及，因而預留監考時數
B6: 已計入五位訓導老巡課室等(每人4小時)的工作
B7: 包括 說話考試(英文科/每人6.75小時) 及
B8: 當中亦包括 說話考試(中文科/每人6.75小時 - 假設全部中文老師參與) 及
B9: 監考工作時數的偏差，將會累積至下一次考試
A10: (B) | B10: 教學助理(TAC, TAE, TAE1, 除TAP 因負責STANDBY 及 TAA 因協助 Kitty 考試事宜 )
B11: 平均約 13.5 小時
A12: (C) | B12: 其他(88, 123, 154, TSS, 除116 因負責改MC)
B13: 平均約 15 小時
A16: 2. 上下監考
B17: 已盡量安排中一至三班主任監考下午、中四至六班主任監考上午
A19: 3. 監考教師缺席
A20: (A) | B20: 如有監考教師缺席，將由 TAP 或 由禮堂監考教師 替代
A21: (B) | B21: 監考教師缺席的工作時數，將會累積至下一次考試
A22: (C) | B22: 因参加校外會議或其他事宜，老師需自行安排調動監考
B23: 工作、填寫有關表格 及得校長批准。惟參加者將不獲
B24: 扣減監考時數
A26: 4. T154 逢星期五OFF

Sheet 每個老師監考表
A1: 日期 | B1: 到場 | C1: 結束 | D1: 級號 | E1: 科目 | F1: 班/組別 | G1: 地點 | H1: 監考老師 | I1: 崗位
A2: 46178 | B2: 0.33333333 | C2: 0.375 | D2: S3 | E2: 生物 | F2: 3B | G2: 302 | H2: 218 | I2: 監考員
A3: 46178 | B3: 0.38541667 | C3: 0.42708333 | D3: S3 | E3: 公民與社會 | F3: 3B | G3: 302 | H3: 218 | I3: 監考員
A4: 46181 | I4: 後備
A5: 46182 | B5: 0.33333333 | C5: 0.40625 | D5: S4 | E5: 經濟 | F5: 選修 | G5: 405 | H5: 218 | I5: 監考員
A6: 46185 | B6: 0.39583333 | C6: 0.51041667 | D6: S5 | E6: 經濟卷二 | F6: 選修 | G6: 405 | H6: 218 | I6: 監考員
A7: 46188 | B7: 0.33333333 | C7: 0.38333333 | D7: S3 | E7: 物理 | F7: SEN | G7: 303 | H7: 218 | I7: 監考員
A8: 46188 | B8: 0.4375 | C8: 0.5 | D8: S3 | E8: 中國語文卷一 | F8: SEN | G8: 303 | H8: 218 | I8: 監考員
A9: 46189 | B9: 0.45833333 | C9: 0.51041667 | D9: S3 | E9: 數學卷二 | F9: 3B | G9: 302 | H9: 218 | I9: 監考員
A10: 46190 | I10: 後備
A11: 46191 | B11: 0.33333333 | C11: 0.375 | D11: S1 | E11: 中史 | F11: 1B | G11: 102 | H11: 218 | I11: 監考員
A12: 46178 | B12: 0.33333333 | C12: 0.40625 | D12: S4 | E12: CHI 1 | F12: 全級 | G12: 禮堂 (HALL) | H12: 138 | I12: 試場主任
A13: 46178 | B13: 0.33333333 | C13: 0.40625 | D13: S4 | E13: CHI 1 | F13: 全級 | G13: 禮堂 (HALL) | H13: S86 | I13: 監考員
A14: 46178 | B14: 0.33333333 | C14: 0.40625 | D14: S4 | E14: CHI 1 | F14: 全級 | G14: 禮堂 (HALL) | H14: 152 | I14: 監考員
A15: 46178 | B15: 0.33333333 | C15: 0.40625 | D15: S4 | E15: CHI 1 | F15: 全級 | G15: 禮堂 (HALL) | H15: 91 | I15: 監考員
A16: 46178 | B16: 0.41666667 | C16: 0.52083333 | D16: S4 | E16: CHI 2 | F16: 全級 | G16: 禮堂 (HALL) | H16: 32 | I16: 試場主任
A17: 46178 | B17: 0.41666667 | C17: 0.52083333 | D17: S4 | E17: CHI 2 | F17: 全級 | G17: 禮堂 (HALL) | H17: S86 | I17: 監考員
A18: 46178 | B18: 0.41666667 | C18: 0.52083333 | D18: S4 | E18: CHI 2 | F18: 全級 | G18: 禮堂 (HALL) | H18: 210 | I18: 監考員
A19: 46178 | B19: 0.41666667 | C19: 0.52083333 | D19: S4 | E19: CHI 2 | F19: 全級 | G19: 禮堂 (HALL) | H19: 103 | I19: 監考員
A20: 46181 | B20: 0.33333333 | C20: 0.40625 | D20: S5 | E20: ENG 1 | F20: 全級 | G20: 禮堂 (HALL) | H20: 3 | I20: 試場主任
A21: 46181 | B21: 0.33333333 | C21: 0.40625 | D21: S5 | E21: ENG 1 | F21: 全級 | G21: 禮堂 (HALL) | H21: 210 | I21: 監考員
A22: 46181 | B22: 0.33333333 | C22: 0.40625 | D22: S5 | E22: ENG 1 | F22: 全級 | G22: 禮堂 (HALL) | H22: S22 | I22: 監考員
A23: 46181 | B23: 0.33333333 | C23: 0.40625 | D23: S5 | E23: ENG 1 | F23: 全級 | G23: 禮堂 (HALL) | H23: 78 | I23: 監考員
A24: 46181 | B24: 0.42708333 | C24: 0.48958333 | D24: S4 | E24: ENG 3 (LIST) | F24: 全級 | G24: 禮堂 (HALL) | H24: 153 | I24: 試場主任
A25: 46181 | B25: 0.42708333 | C25: 0.48958333 | D25: S4 | E25: ENG 3 (LIST) | F25: 全級 | G25: 禮堂 (HALL) | H25: 210 | I25: 監考員
A26: 46181 | B26: 0.42708333 | C26: 0.48958333 | D26: S4 | E26: ENG 3 (LIST) | F26: 全級 | G26: 禮堂 (HALL) | H26: 137 | I26: 監考員
A27: 46181 | B27: 0.42708333 | C27: 0.48958333 | D27: S4 | E27: ENG 3 (LIST) | F27: 全級 | G27: 禮堂 (HALL) | H27: 112 | I27: 監考員
A28: 46182 | B28: 0.33333333 | C28: 0.38541667 | D28: S1 | E28: ENG 2 | F28: 全級 | G28: 禮堂 (HALL) | H28: 138 | I28: 試場主任
A29: 46182 | B29: 0.33333333 | C29: 0.38541667 | D29: S1 | E29: ENG 2 | F29: 全級 | G29: 禮堂 (HALL) | H29: S86 | I29: 監考員
A30: 46182 | B30: 0.33333333 | C30: 0.38541667 | D30: S1 | E30: ENG 2 | F30: 全級 | G30: 禮堂 (HALL) | H30: 72 | I30: 監考員
A31: 46182 | B31: 0.33333333 | C31: 0.38541667 | D31: S1 | E31: ENG 2 | F31: 全級 | G31: 禮堂 (HALL) | H31: 73 | I31: 監考員
A32: 46183 | B32: 0.39583333 | C32: 0.46875 | D32: S1 | E32: ENG 3 (LIST) | F32: 全級 | G32: 禮堂 (HALL) | H32: 128 | I32: 試場主任
A33: 46183 | B33: 0.39583333 | C33: 0.46875 | D33: S1 | E33: ENG 3 (LIST) | F33: 全級 | G33: 禮堂 (HALL) | H33: 214 | I33: 監考員
A34: 46183 | B34: 0.39583333 | C34: 0.46875 | D34: S1 | E34: ENG 3 (LIST) | F34: 全級 | G34: 禮堂 (HALL) | H34: 92 | I34: 監考員
A35: 46183 | B35: 0.39583333 | C35: 0.46875 | D35: S1 | E35: ENG 3 (LIST) | F35: 全級 | G35: 禮堂 (HALL) | H35: 73 | I35: 監考員
A36: 46183 | B36: 0.34375 | C36: 0.38541667 | D36: S3 | E36: G.T./G. | F36: 全級 | G36: 禮堂 (HALL) | H36: 32 | I36: 試場主任

Sheet FEx_Workload
B1: VERSION 7.6.2024 | K1: FINAL EXAM | N1: SECOND TERM TEST | Q1: FIRST TERM EXAM | T1: FIRST TERM TEST | W1: =B1 -> VERSION 7.6.2024 | Y1: =#REF! -> #REF! | AA1: 23-24 FINAL | AH1: Weight (S2-5) | AI1: 1
A2: TEACHERS | B2: Code | C2: Inv. Time (Standard) | F2: SEN Invigilation | G2: OTHER DUTIES | H2: Discipline | J2: Chi/Eng/Pu Speaking | K2: TOTAL INVIL. TIME | L2: INV. RATIO | M2: INVIL. DUTY TO BE FULFILLED | N2: TOTAL INVIL. TIME | O2: INV. RATIO | P2: INVIL. DUTY TO BE FULFILLED | Q2: TOTAL INVIL. TIME | R2: INV. RATIO | S2: INVIL. DUTY TO BE FULFILLED | T2: TOTAL INVIL. TIME | U2: INV. RATIO | V2: INVIL. DUTY TO BE FULFILLED | W2: BALANCE | X2: Teachers' Name | Y2: Code | AA2: English Panel | AB2: E1 | AC2: E2 | AD2: E3 | AE2: E4 | AF2: E5 | AG2: E6
A3: LYY | B3: 3 | C3: =SUMIF(#REF!,B3,#REF!) -> #REF! | F3: ='SEN INIL'!BV2 -> 2.4666667 | H3: =AB42 -> 3 | J3: =AI3 -> 5.7266667 | K3: =SUM(C3:J3) -> #REF! | L3: ='INV. RATIO(FINAL EXAM)'!AM5 -> 24.5 | M3: =$K$66*L3/$L$66 -> #REF! | N3: 3.5 | O3: 24.3 | P3: 4.1468127 | Q3: 12.2 | R3: 44.9 | S3: 15.669292 | T3: 8 | U3: 19.1 | V3: 6.1103463 | W3: =K3-M3+Q3-S3+T3-V3+N3-P3 -> #REF! | X3: =A3 -> LYY | Y3: =B3 -> 3 | AA3: 3 | AB3: 0.75 | AC3: 0.75 | AD3: 0.75 | AE3: 1.56 | AF3: =1+55/60 -> 1.9166667 | AH3: =SUM(AB3:AG3) -> 5.7266667 | AI3: =AB3+SUM(AC3:AG3)*AI$1 -> 5.7266667
A4: LMT | B4: 4 | C4: =SUMIF(#REF!,B4,#REF!) -> #REF! | F4: ='SEN INIL'!BV3 -> 0 | K4: =SUM(C4:J4) -> #REF! | L4: ='INV. RATIO(FINAL EXAM)'!AM6 -> 23 | M4: =$K$66*L4/$L$66 -> #REF! | N4: 1.25 | O4: 25 | P4: 4.2662683 | Q4: 16 | R4: 45.8 | S4: 15.983375 | T4: 8 | U4: 19.8 | V4: 6.3342857 | W4: =K4-M4+Q4-S4+T4-V4+N4-P4 -> #REF! | X4: =A4 -> LMT | Y4: =B4 -> 4 | AA4: 22 | AB4: 0.75 | AC4: 0.75 | AD4: 0.75 | AE4: 1.56 | AF4: 1.9166667 | AH4: =SUM(AB4:AG4) -> 5.7266667 | AI4: =AB4+SUM(AC4:AG4)*AI$1 -> 5.7266667
A5: LWH | B5: 5 | C5: =SUMIF(#REF!,B5,#REF!) -> #REF! | F5: ='SEN INIL'!BV4 -> 3.7 | K5: =SUM(C5:J5) -> #REF! | L5: ='INV. RATIO(FINAL EXAM)'!AM7 -> 23 | M5: =$K$66*L5/$L$66 -> #REF! | N5: 3.25 | O5: 23 | P5: 3.9249668 | Q5: 15.2 | R5: 42 | S5: 14.657244 | T5: 7 | U5: 22 | V5: 7.0380952 | W5: =K5-M5+Q5-S5+T5-V5+N5-P5 -> #REF! | X5: =A5 -> LWH | Y5: =B5 -> 5 | AA5: 39 | AB5: 0.75 | AC5: 0.75 | AD5: 0.75 | AE5: 1.95 | AF5: 1.9166667 | AH5: =SUM(AB5:AG5) -> 6.1166667 | AI5: =AB5+SUM(AC5:AG5)*AI$1 -> 6.1166667
A6: LWT | B6: 20 | C6: =SUMIF(#REF!,B6,#REF!) -> #REF! | F6: ='SEN INIL'!BV5 -> 3 | K6: =SUM(C6:J6) -> #REF! | L6: ='INV. RATIO(FINAL EXAM)'!AM8 -> 20.5 | M6: =$K$66*L6/$L$66 -> #REF! | N6: 2.0833333 | O6: 19.8 | P6: 3.3788845 | Q6: 15.2 | R6: 37.4 | S6: 13.051927 | T6: 9.3 | U6: 18.6 | V6: 5.9503896 | W6: =K6-M6+Q6-S6+T6-V6+N6-P6 -> #REF! | X6: =A6 -> LWT | Y6: =B6 -> 20 | AA6: 67 | AB6: 0.75 | AE6: 1.55 | AF6: 1.9166667 | AH6: =SUM(AB6:AG6) -> 4.2166667 | AI6: =AB6+SUM(AC6:AG6)*AI$1 -> 4.2166667 | AN6: 突
A7: WWY | B7: 22 | C7: =SUMIF(#REF!,B7,#REF!) -> #REF! | F7: ='SEN INIL'!BV6 -> 2.6 | J7: =AI4 -> 5.7266667 | K7: =SUM(C7:J7) -> #REF! | L7: ='INV. RATIO(FINAL EXAM)'!AM9 -> 25.5 | M7: =$K$66*L7/$L$66 -> #REF! | N7: 6.8333333 | O7: 25.7 | P7: 4.3857238 | Q7: 10.3 | R7: 43.8 | S7: 15.285411 | T7: 5 | U7: 22.5 | V7: 7.1980519 | W7: =K7-M7+Q7-S7+T7-V7+N7-P7 -> #REF! | X7: =A7 -> WWY | Y7: =B7 -> 22 | AA7: 76 | AE7: 1.55 | AF7: 1.9166667 | AH7: =SUM(AB7:AG7) -> 3.4666667 | AI7: =AB7+SUM(AC7:AG7)*AI$1 -> 3.4666667
A8: LCS | B8: 25 | C8: =SUMIF(#REF!,B8,#REF!) -> #REF! | F8: ='SEN INIL'!BV7 -> 4.6666667 | K8: =SUM(C8:J8) -> #REF! | L8: ='INV. RATIO(FINAL EXAM)'!AM10 -> 12 | M8: =$K$66*L8/$L$66 -> #REF! | N8: 0 | O8: 16 | P8: 2.7304117 | Q8: 14.7 | R8: 25 | S8: 8.7245499 | T8: 4 | U8: 16 | V8: 5.1186147 | W8: =K8-M8+Q8-S8+T8-V8+N8-P8 -> #REF! | X8: =A8 -> LCS | Y8: =B8 -> 25 | AA8: 85 | AC8: 0.75 | AD8: 1 | AH8: =SUM(AB8:AG8) -> 1.75 | AI8: =AB8+SUM(AC8:AG8)*AI$1 -> 1.75
A9: LPK | B9: 32 | C9: =SUMIF(#REF!,B9,#REF!) -> #REF! | F9: ='SEN INIL'!BV8 -> 0 | G9: =2+5/60 -> 2.0833333 | K9: =SUM(C9:J9) -> #REF! | L9: ='INV. RATIO(FINAL EXAM)'!AM11 -> 15 | M9: =$K$66*L9/$L$66 -> #REF! | N9: 3.5 | O9: 17 | P9: 2.9010624 | Q9: 14.6 | R9: 31 | S9: 10.818442 | T9: 6.1 | U9: 14 | V9: 4.4787879 | W9: =K9-M9+Q9-S9+T9-V9+N9-P9 -> #REF! | X9: =A9 -> LPK | Y9: =B9 -> 32 | AA9: 128 | AC9: 0.75 | AD9: 0.75 | AE9: 1.55 | AF9: 1.9166667 | AH9: =SUM(AB9:AG9) -> 4.9666667 | AI9: =AB9+SUM(AC9:AG9)*AI$1 -> 4.9666667
A10: WLP | B10: 37 | C10: =SUMIF(#REF!,B10,#REF!) -> #REF! | F10: ='SEN INIL'!BV9 -> 1.4333333 | G10: =1.25 -> 1.25 | K10: =SUM(C10:J10) -> #REF! | L10: ='INV. RATIO(FINAL EXAM)'!AM12 -> 23.5 | M10: =$K$66*L10/$L$66 -> #REF! | N10: 3.5 | O10: 25.5 | P10: 4.3515936 | Q10: 13.8 | R10: 42.8 | S10: 14.936429 | T10: 6.1 | U10: 21.3 | V10: 6.8141558 | W10: =K10-M10+Q10-S10+T10-V10+N10-P10 -> #REF! | X10: =A10 -> WLP | Y10: =B10 -> 37 | AA10: 135 | AB10: 0.75 | AC10: 0.75 | AD10: 0.75 | AE10: 1.55 | AF10: 1.9166667 | AH10: =SUM(AB10:AG10) -> 5.7166667 | AI10: =AB10+SUM(AC10:AG10)*AI$1 -> 5.7166667
A11: CML | B11: 39 | C11: =SUMIF(#REF!,B11,#REF!) -> #REF! | F11: ='SEN INIL'!BV10 -> 0 | J11: =AI5 -> 6.1166667 | K11: =SUM(C11:J11) -> #REF! | L11: ='INV. RATIO(FINAL EXAM)'!AM13 -> 24 | M11: =$K$66*L11/$L$66 -> #REF! | N11: 5 | O11: 25 | P11: 4.2662683 | Q11: 12 | R11: 40 | S11: 13.95928 | T11: 6.5 | U11: 22 | V11: 7.0380952 | W11: =K11-M11+Q11-S11+T11-V11+N11-P11 -> #REF! | X11: =A11 -> CML | Y11: =B11 -> 39 | AA11: 147 | AB11: 0.75 | AC11: 0.75 | AD11: 0.75 | AE11: 1.95 | AF11: 1.9166667 | AH11: =SUM(AB11:AG11) -> 6.1166667 | AI11: =AB11+SUM(AC11:AG11)*AI$1 -> 6.1166667
A12: TCH | B12: 49 | C12: =SUMIF(#REF!,B12,#REF!) -> #REF! | F12: ='SEN INIL'!BV11 -> 4.05 | K12: =SUM(C12:J12) -> #REF! | L12: ='INV. RATIO(FINAL EXAM)'!AM14 -> 25.5 | M12: =$K$66*L12/$L$66 -> #REF! | N12: 5.75 | O12: 21.5 | P12: 3.6689907 | Q12: 12 | R12: 39.8 | S12: 13.889483 | T12: 4.3 | U12: 17.3 | V12: 5.5345022 | W12: =K12-M12+Q12-S12+T12-V12+N12-P12 -> #REF! | X12: =A12 -> TCH | Y12: =B12 -> 49 | AA12: 190 | AB12: 0.75 | AC12: 0.75 | AD12: 0.75 | AE12: 1.55 | AF12: 1.9166667 | AH12: =SUM(AB12:AG12) -> 5.7166667 | AI12: =AB12+SUM(AC12:AG12)*AI$1 -> 5.7166667
A13: LTN | B13: 67 | C13: =SUMIF(#REF!,B13,#REF!) -> #REF! | F13: ='SEN INIL'!BV12 -> 0 | J13: =AI6 -> 4.2166667 | K13: =SUM(C13:J13) -> #REF! | L13: ='INV. RATIO(FINAL EXAM)'!AM15 -> 26.5 | M13: =$K$66*L13/$L$66*6/10 -> #REF! | N13: 2.5 | O13: 22.3 | P13: 3.8055113 | Q13: 13.1 | R13: 37.9 | S13: 13.226418 | T13: 7.3 | U13: 16.1 | V13: 5.1506061 | W13: =K13-M13+Q13-S13+T13-V13+N13-P13 -> #REF! | X13: =A13 -> LTN | Y13: =B13 -> 67 | AA13: 214 | AB13: 0.75 | AC13: 0.75 | AD13: 0.75 | AE13: 1.55 | AF13: 1.9166667 | AH13: =SUM(AB13:AG13) -> 5.7166667 | AI13: =AB13+SUM(AC13:AG13)*AI$1 -> 5.7166667
A14: LPC | B14: 72 | C14: =SUMIF(#REF!,B14,#REF!) -> #REF! | F14: ='SEN INIL'!BV13 -> 0 | J14: =AI25 -> 2 | K14: =SUM(C14:J14) -> #REF! | L14: ='INV. RATIO(FINAL EXAM)'!AM16 -> 21 | M14: =$K$66*L14/$L$66 -> #REF! | N14: 4.75 | O14: 19 | P14: 3.2423639 | Q14: 13.2 | R14: 30 | S14: 10.46946 | T14: 5.8 | U14: 15 | V14: 4.7987013 | W14: =K14-M14+Q14-S14+T14-V14+N14-P14 -> #REF! | X14: =A14 -> LPC | Y14: =B14 -> 72 | AA14: 216 | AB14: 0.75 | AC14: 0.75 | AD14: 0.75 | AE14: 1.55 | AF14: 1.9166667 | AH14: =SUM(AB14:AG14) -> 5.7166667 | AI14: =AB14+SUM(AC14:AG14)*AI$1 -> 5.7166667
A15: LHK | B15: 73 | C15: =SUMIF(#REF!,B15,#REF!) -> #REF! | F15: ='SEN INIL'!BV14 -> 0 | K15: =SUM(C15:J15) -> #REF! | L15: ='INV. RATIO(FINAL EXAM)'!AM17 -> 23 | M15: =$K$66*L15/$L$66 -> #REF! | N15: 4.75 | O15: 27 | P15: 4.6075697 | Q15: 15.1 | R15: 45.8 | S15: 15.983375 | T15: 8.6 | U15: 22.8 | V15: 7.294026 | W15: =K15-M15+Q15-S15+T15-V15+N15-P15 -> #REF! | X15: =A15 -> LHK | Y15: =B15 -> 73 | AA15: S67 | AH15: =SUM(AB15:AG15) -> 0 | AI15: =AB15+SUM(AC15:AG15)*AI$1 -> 0
A16: WWY | B16: 76 | C16: =SUMIF(#REF!,B16,#REF!) -> #REF! | F16: ='SEN INIL'!BV15 -> 0 | J16: =AI7 -> 3.4666667 | K16: =SUM(C16:J16) -> #REF! | L16: ='INV. RATIO(FINAL EXAM)'!AM18 -> 12 | M16: =$K$66*L16/$L$66 -> #REF! | N16: 4.5 | O16: 12 | P16: 2.0478088 | Q16: 4 | R16: 26.5 | S16: 9.2480229 | T16: 0 | U16: 9 | V16: 2.8792208 | W16: =K16-M16+Q16-S16+T16-V16+N16-P16 -> #REF! | X16: =A16 -> WWY | Y16: =B16 -> 76 | AH16: =SUM(AB16:AG16) -> 0 | AI16: =AB16+SUM(AC16:AG16)*AI$1 -> 0
A17: LKC | B17: 78 | C17: =SUMIF(#REF!,B17,#REF!) -> #REF! | F17: ='SEN INIL'!BV16 -> 1.75 | K17: =SUM(C17:J17) -> #REF! | L17: ='INV. RATIO(FINAL EXAM)'!AM19 -> 23.5 | M17: =$K$66*L17/$L$66 -> #REF! | N17: 3.75 | O17: 27.7 | P17: 4.7270252 | Q17: 13.7 | R17: 46.1 | S17: 16.08807 | T17: 8.7 | U17: 27.9 | V17: 8.9255844 | W17: =K17-M17+Q17-S17+T17-V17+N17-P17 -> #REF! | X17: =A17 -> LKC | Y17: =B17 -> 78 | AH17: =SUM(AB17:AG17) -> 0 | AI17: =AB17+SUM(AC17:AG17)*AI$1 -> 0
A18: KKW | B18: 84 | C18: =SUMIF(#REF!,B18,#REF!) -> #REF! | F18: ='SEN INIL'!BV17 -> 3 | K18: =SUM(C18:J18) -> #REF! | L18: ='INV. RATIO(FINAL EXAM)'!AM20 -> 23.5 | M18: =$K$66*L18/$L$66 -> #REF! | N18: 1.5 | O18: 27.3 | P18: 4.6587649 | Q18: 15.6 | R18: 42.9 | S18: 14.971328 | T18: 6.8 | U18: 23.1 | V18: 7.39 | W18: =K18-M18+Q18-S18+T18-V18+N18-P18 -> #REF! | X18: =A18 -> KKW | Y18: =B18 -> 84 | AH18: =SUM(AB18:AG18) -> 0 | AI18: =AB18+SUM(AC18:AG18)*AI$1 -> 0
A19: AT | B19: 85 | C19: =SUMIF(#REF!,B19,#REF!) -> #REF! | F19: ='SEN INIL'!BV18 -> 0 | J19: =AI8 -> 1.75 | K19: =SUM(C19:J19) -> #REF! | L19: ='INV. RATIO(FINAL EXAM)'!AM21 -> 15 | M19: =$K$66*L19/$L$66 -> #REF! | N19: 0 | O19: 15 | P19: 2.559761 | Q19: 14.1 | R19: 21 | S19: 7.3286219 | T19: 8.7 | U19: 11 | V19: 3.5190476 | W19: =K19-M19+Q19-S19+T19-V19+N19-P19 -> #REF! | X19: =A19 -> AT | Y19: =B19 -> 85 | AH19: =SUM(AB19:AG19) -> 0 | AI19: =AB19+SUM(AC19:AG19)*AI$1 -> 0
A20: KSC | B20: 86 | C20: =SUMIF(#REF!,B20,#REF!) -> #REF! | F20: ='SEN INIL'!BV19 -> 0 | J20: =AI26 -> 1 | K20: =SUM(C20:J20) -> #REF! | L20: ='INV. RATIO(FINAL EXAM)'!AM22 -> 24 | M20: =$K$66*L20/$L$66 -> #REF! | N20: 5.8333333 | O20: 26.7 | P20: 4.5563745 | Q20: 14.2 | R20: 40.3 | S20: 14.063974 | T20: 6 | U20: 21 | V20: 6.7181818 | W20: =K20-M20+Q20-S20+T20-V20+N20-P20 -> #REF! | X20: =A20 -> KSC | Y20: =B20 -> 86 | AH20: =SUM(AB20:AG20) -> 0 | AI20: =AB20+SUM(AC20:AG20)*AI$1 -> 0
A21: LKL | B21: 90 | C21: =SUMIF(#REF!,B21,#REF!) -> #REF! | F21: ='SEN INIL'!BV20 -> 0 | J21: =AI27 -> 2 | K21: =SUM(C21:J21) -> #REF! | L21: ='INV. RATIO(FINAL EXAM)'!AM23 -> 20.5 | M21: =$K$66*L21/$L$66 -> #REF! | N21: 3.25 | O21: 21.3 | P21: 3.6348606 | Q21: 12.5 | R21: 30.9 | S21: 10.783544 | T21: 5.5 | U21: 15.1 | V21: 4.8306926 | W21: =K21-M21+Q21-S21+T21-V21+N21-P21 -> #REF! | X21: =A21 -> LKL | Y21: =B21 -> 90 | AA21: Duration | AI21: =SUM(AI3:AI20) -> 60.953333
A22: KLH | B22: 91 | C22: =SUMIF(#REF!,B22,#REF!) -> #REF! | F22: ='SEN INIL'!BV21 -> 12.65 | K22: =SUM(C22:J22) -> #REF! | L22: ='INV. RATIO(FINAL EXAM)'!AM24 -> 25.5 | M22: =$K$66*L22/$L$66 -> #REF! | N22: 6.0833333 | O22: 27.7 | P22: 4.7270252 | Q22: 14 | R22: 42.3 | S22: 14.761938 | T22: 6.8 | U22: 22 | V22: 7.0380952 | W22: =K22-M22+Q22-S22+T22-V22+N22-P22 -> #REF! | X22: =A22 -> KLH | Y22: =B22 -> 91
A23: CKS | B23: 92 | C23: =SUMIF(#REF!,B23,#REF!) -> #REF! | F23: ='SEN INIL'!BV22 -> 0 | K23: =SUM(C23:J23) -> #REF! | L23: ='INV. RATIO(FINAL EXAM)'!AM25 -> 22.5 | M23: =$K$66*L23/$L$66 -> #REF! | N23: 4.0833333 | O23: 20.3 | P23: 3.4642098 | Q23: 13.1 | R23: 31.9 | S23: 11.132526 | T23: 6.5 | U23: 13.1 | V23: 4.1908658 | W23: =K23-M23+Q23-S23+T23-V23+N23-P23 -> #REF! | X23: =A23 -> CKS | Y23: =B23 -> 92
A24: CKM | B24: 102 | C24: =SUMIF(#REF!,B24,#REF!) -> #REF! | F24: ='SEN INIL'!BV23 -> 0 | J24: =AI28 -> 2 | K24: =SUM(C24:J24) -> #REF! | L24: ='INV. RATIO(FINAL EXAM)'!AM26 -> 24 | M24: =$K$66*L24/$L$66 -> #REF! | N24: 2.5833333 | O24: 26.2 | P24: 4.4710491 | Q24: 14.4 | R24: 47.8 | S24: 16.681339 | T24: 6.7 | U24: 23 | V24: 7.3580087 | W24: =K24-M24+Q24-S24+T24-V24+N24-P24 -> #REF! | X24: =A24 -> CKM | Y24: =B24 -> 102 | AA24: Chinese Panel | AB24: C1 | AC24: C2 | AD24: C3
A25: LKF | B25: 103 | C25: =SUMIF(#REF!,B25,#REF!) -> #REF! | F25: ='SEN INIL'!BV24 -> 5.9333333 | K25: =SUM(C25:J25) -> #REF! | L25: ='INV. RATIO(FINAL EXAM)'!AM27 -> 22 | M25: =$K$66*L25/$L$66 -> #REF! | N25: 4.75 | O25: 28.2 | P25: 4.8123506 | Q25: 14.5 | R25: 44.8 | S25: 15.634393 | T25: 6.3 | U25: 25 | V25: 7.9978355 | W25: =K25-M25+Q25-S25+T25-V25+N25-P25 -> #REF! | X25: =A25 -> LKF | Y25: =B25 -> 103 | AA25: 72 | AB25: 1 | AC25: 1 | AI25: =SUM(AB25:AH25) -> 2
A26: CKW | B26: 112 | C26: =SUMIF(#REF!,B26,#REF!) -> #REF! | F26: ='SEN INIL'!BV25 -> 3 | H26: =AB43 -> 3 | K26: =SUM(C26:J26) -> #REF! | L26: ='INV. RATIO(FINAL EXAM)'!AM28 -> 24.5 | M26: =$K$66*L26/$L$66 -> #REF! | N26: 3 | O26: 24.3 | P26: 4.1468127 | Q26: 12.3 | R26: 40.9 | S26: 14.273364 | T26: 7.3 | U26: 22.1 | V26: 7.0700866 | W26: =K26-M26+Q26-S26+T26-V26+N26-P26 -> #REF! | X26: =A26 -> CKW | Y26: =B26 -> 112 | AA26: 86 | AC26: 1 | AI26: =SUM(AB26:AH26) -> 1
A27: LWK | B27: 113 | C27: =SUMIF(#REF!,B27,#REF!) -> #REF! | F27: ='SEN INIL'!BV26 -> 7.8166667 | K27: =SUM(C27:J27) -> #REF! | L27: ='INV. RATIO(FINAL EXAM)'!AM29 -> 22.5 | M27: =$K$66*L27/$L$66 -> #REF! | N27: 2.5 | O27: 25.7 | P27: 4.3857238 | Q27: 14.8 | R27: 48.1 | S27: 16.786034 | T27: 7.2 | U27: 24.9 | V27: 7.9658442 | W27: =K27-M27+Q27-S27+T27-V27+N27-P27 -> #REF! | X27: =A27 -> LWK | Y27: =B27 -> 113 | AA27: 90 | AB27: 1 | AC27: 1 | AI27: =SUM(AB27:AH27) -> 2
A28: CYP | B28: 114 | C28: =SUMIF(#REF!,B28,#REF!) -> #REF! | F28: ='SEN INIL'!BV27 -> 11.75 | G28: =-1-27/60 -> -1.45 | K28: =SUM(C28:J28) -> #REF! | L28: ='INV. RATIO(FINAL EXAM)'!AM30 -> 23 | M28: =$K$66*L28/$L$66 -> #REF! | N28: 3.75 | O28: 25 | P28: 4.2662683 | Q28: 14.9 | R28: 44.4 | S28: 15.494801 | T28: 7 | U28: 19.6 | V28: 6.270303 | W28: =K28-M28+Q28-S28+T28-V28+N28-P28 -> #REF! | X28: =A28 -> CYP | Y28: =B28 -> 114 | AA28: 102 | AB28: 1 | AC28: 1 | AI28: =SUM(AB28:AH28) -> 2
A29: LWC | B29: 117 | C29: =SUMIF(#REF!,B29,#REF!) -> #REF! | F29: ='SEN INIL'!BV28 -> 0 | K29: =SUM(C29:J29) -> #REF! | L29: ='INV. RATIO(FINAL EXAM)'!AM31 -> 12 | M29: =$K$66*L29/$L$66 -> #REF! | N29: 5.5 | O29: 13 | P29: 2.2184595 | Q29: 2.8 | R29: 26 | S29: 9.0735319 | T29: 0 | U29: 10 | V29: 3.1991342 | W29: =K29-M29+Q29-S29+T29-V29+N29-P29 -> #REF! | X29: =A29 -> LWC | Y29: =B29 -> 117 | AA29: 137 | AB29: 1 | AI29: =SUM(AB29:AH29) -> 1
A30: WYC | B30: 120 | C30: =SUMIF(#REF!,B30,#REF!) -> #REF! | F30: ='SEN INIL'!BV29 -> 2.7333333 | H30: =AB44 -> 3 | K30: =SUM(C30:J30) -> #REF! | L30: ='INV. RATIO(FINAL EXAM)'!AM32 -> 21.5 | M30: =$K$66*L30/$L$66 -> #REF! | N30: 5.5 | O30: 25.7 | P30: 4.3857238 | Q30: 13.6 | R30: 42.8 | S30: 14.936429 | T30: 5.5 | U30: 22.5 | V30: 7.1980519 | W30: =K30-M30+Q30-S30+T30-V30+N30-P30 -> #REF! | X30: =A30 -> WYC | Y30: =B30 -> 120 | AA30: 138 | AB30: 1 | AC30: 1 | AI30: =SUM(AB30:AH30) -> 2
A31: LHY | B31: 128 | C31: =SUMIF(#REF!,B31,#REF!) -> #REF! | F31: ='SEN INIL'!BV30 -> 0 | J31: =AI9 -> 4.9666667 | K31: =SUM(C31:J31) -> #REF! | L31: ='INV. RATIO(FINAL EXAM)'!AM33 -> 24 | M31: =$K$66*L31/$L$66 -> #REF! | N31: 2 | O31: 24 | P31: 4.0956175 | Q31: 12.8 | R31: 38.4 | S31: 13.400909 | T31: 6.8 | U31: 16.6 | V31: 5.3105628 | W31: =K31-M31+Q31-S31+T31-V31+N31-P31 -> #REF! | X31: =A31 -> LHY | Y31: =B31 -> 128 | AA31: 141 | AB31: 1 | AI31: =SUM(AB31:AH31) -> 1
A32: HNY | B32: 129 | C32: =SUMIF(#REF!,B32,#REF!) -> #REF! | F32: ='SEN INIL'!BV31 -> 6.8833333 | K32: =SUM(C32:J32) -> #REF! | L32: ='INV. RATIO(FINAL EXAM)'!AM34 -> 22 | M32: =$K$66*L32/$L$66 -> #REF! | N32: 4.5 | O32: 25 | P32: 4.2662683 | Q32: 14.7 | R32: 45.3 | S32: 15.808884 | T32: 4.8 | U32: 21.8 | V32: 6.9741126 | W32: =K32-M32+Q32-S32+T32-V32+N32-P32 -> #REF! | X32: =A32 -> HNY | Y32: =B32 -> 129 | AA32: 152 | AB32: 1 | AC32: 1 | AI32: =SUM(AB32:AH32) -> 2
A33: HBL | B33: 134 | C33: =SUMIF(#REF!,B33,#REF!) -> #REF! | F33: ='SEN INIL'!BV32 -> 4.2166667 | K33: =SUM(C33:J33) -> #REF! | L33: ='INV. RATIO(FINAL EXAM)'!AM35 -> 22 | M33: =$K$66*L33/$L$66 -> #REF! | N33: 2.0833333 | O33: 21 | P33: 3.5836653 | Q33: 13.8 | R33: 42 | S33: 14.657244 | T33: 5.8 | U33: 18 | V33: 5.7584416 | W33: =K33-M33+Q33-S33+T33-V33+N33-P33 -> #REF! | X33: =A33 -> HBL | Y33: =B33 -> 134 | AA33: 181 | AC33: 1 | AI33: =SUM(AB33:AH33) -> 1
A34: WWS | B34: 135 | C34: =SUMIF(#REF!,B34,#REF!) -> #REF! | F34: ='SEN INIL'!BV33 -> 0 | J34: =AI10 -> 5.7166667 | K34: =SUM(C34:J34) -> #REF! | L34: ='INV. RATIO(FINAL EXAM)'!AM36 -> 25.5 | M34: =$K$66*L34/$L$66 -> #REF! | N34: 4.5 | O34: 24.3 | P34: 4.1468127 | Q34: 12.1 | R34: 37.9 | S34: 13.226418 | T34: 5.7 | U34: 18.1 | V34: 5.7904329 | W34: =K34-M34+Q34-S34+T34-V34+N34-P34 -> #REF! | X34: =A34 -> WWS | Y34: =B34 -> 135 | AA34: 201 | AC34: 1 | AI34: =SUM(AB34:AH34) -> 1
A35: CHB | B35: 137 | C35: =SUMIF(#REF!,B35,#REF!) -> #REF! | F35: ='SEN INIL'!BV34 -> 0 | J35: =AI29 -> 1 | K35: =SUM(C35:J35) -> #REF! | L35: ='INV. RATIO(FINAL EXAM)'!AM37 -> 24 | M35: =$K$66*L35/$L$66 -> #REF! | N35: 5 | O35: 21 | P35: 3.5836653 | Q35: 14 | R35: 35.4 | S35: 12.353963 | T35: 3 | U35: 13.6 | V35: 4.3508225 | W35: =K35-M35+Q35-S35+T35-V35+N35-P35 -> #REF! | X35: =A35 -> CHB | Y35: =B35 -> 137 | AA35: 204 | AB35: 1 | AI35: =SUM(AB35:AH35) -> 1
A36: LWY | B36: 138 | C36: =SUMIF(#REF!,B36,#REF!) -> #REF! | F36: ='SEN INIL'!BV35 -> 4.8166667 | J36: =AI30 -> 2 | K36: =SUM(C36:J36) -> #REF! | L36: ='INV. RATIO(FINAL EXAM)'!AM38 -> 22.5 | M36: =$K$66*L36/$L$66 -> #REF! | N36: 3.25 | O36: 23.5 | P36: 4.0102922 | Q36: 14.4 | R36: 43.8 | S36: 15.285411 | T36: 5.5 | U36: 22.3 | V36: 7.1340693 | W36: =K36-M36+Q36-S36+T36-V36+N36-P36 -> #REF! | X36: =A36 -> LWY | Y36: =B36 -> 138 | AA36: 209 | AB36: 1 | AC36: 1 | AI36: =SUM(AB36:AH36) -> 2
A37: LCM | B37: 140 | C37: =SUMIF(#REF!,B37,#REF!) -> #REF! | F37: ='SEN INIL'!BV36 -> 0 | K37: =SUM(C37:J37) -> #REF! | L37: ='INV. RATIO(FINAL EXAM)'!AM39 -> 12 | M37: =$K$66*L37/$L$66 -> #REF! | N37: 0 | O37: 10 | P37: 1.7065073 | Q37: 15.2 | R37: 16 | S37: 5.5837119 | T37: 9.5 | U37: 5 | V37: 1.5995671 | W37: =K37-M37+Q37-S37+T37-V37+N37-P37 -> #REF! | X37: =A37 -> LCM | Y37: =B37 -> 140 | AA37: 213 | AC37: 1 | AI37: =SUM(AB37:AH37) -> 1
A38: LSY | B38: 141 | C38: =SUMIF(#REF!,B38,#REF!) -> #REF! | F38: ='SEN INIL'!BV37 -> 0 | J38: =AI31 -> 1 | K38: =SUM(C38:J38) -> #REF! | L38: ='INV. RATIO(FINAL EXAM)'!AM40 -> 14 | M38: =$K$66*L38/$L$66 -> #REF! | N38: 2.5 | O38: 12 | P38: 2.0478088 | Q38: 13 | R38: 22 | S38: 7.6776039 | T38: 6.8 | U38: 9 | V38: 2.8792208 | W38: =K38-M38+Q38-S38+T38-V38+N38-P38 -> #REF! | X38: =A38 -> LSY | Y38: =B38 -> 141 | AA38: 217 | AB38: 1 | AI38: =SUM(AB38:AH38) -> 1
A39: WKW | B39: 147 | C39: =SUMIF(#REF!,B39,#REF!) -> #REF! | F39: ='SEN INIL'!BV38 -> 3.65 | J39: =AI11 -> 6.1166667 | K39: =SUM(C39:J39) -> #REF! | L39: ='INV. RATIO(FINAL EXAM)'!AM41 -> 23.5 | M39: =$K$66*L39/$L$66 -> #REF! | N39: 5.5833333 | O39: 24.5 | P39: 4.1809429 | Q39: 13.3 | R39: 51.8 | S39: 18.077267 | T39: 7.3 | U39: 25.3 | V39: 8.0938095 | W39: =K39-M39+Q39-S39+T39-V39+N39-P39 -> #REF! | X39: =A39 -> WKW | Y39: =B39 -> 147 | AI39: =SUM(AI25:AI38) -> 20
A40: CTY | B40: 152 | C40: =SUMIF(#REF!,B40,#REF!) -> #REF! | F40: ='SEN INIL'!BV39 -> 0 | G40: =1+27/60 -> 1.45 | H40: =AB45 -> 3 | J40: =AI32 -> 2 | K40: =SUM(C40:J40) -> #REF! | L40: ='INV. RATIO(FINAL EXAM)'!AM42 -> 21.5 | M40: =$K$66*L40/$L$66 -> #REF! | N40: 3.3333333 | O40: 22.7 | P40: 3.8737716 | Q40: 12.2 | R40: 31.8 | S40: 11.097627 | T40: 6.3 | U40: 17.5 | V40: 5.5984848 | W40: =K40-M40+Q40-S40+T40-V40+N40-P40 -> #REF! | X40: =A40 -> CTY | Y40: =B40 -> 152
...

Sheet SEN INIL
B1: S1 | C1: S2 | D1: S3 | E1: S4 | F1: S5 | G1: VA | H1: S5(SST) phy lab | I1: S5(SST) IS lab | K1: S1 | O1: INVIL | P1: Supp | R1: S2 | V1: INVIL | W1: Supp | Y1: S3 | AC1: INVIL | AD1: Supp | AF1: S4 | AJ1: INVIL | AK1: Supp | AL1: S5 | AP1: INVIL | AQ1: Supp | AS1: S5(SST) phy lab | AW1: INVIL | AX1: Supp | AY1: S5(SST) IS lab | BC1: INVIL | BD1: Supp | BE1: LEAVE | BM1: Teacher | BN1: hrs:mins | BO1: decimal | BQ1: Support | BR1: hrs:mins | BS1: decimal
A2: 11/6/2024 TUE | B2: 8:05 - 9:17 | C2: 8:05 - 9:17 | D2: 8:05 - 9:17 | E2: 8:05 - 10:03 | F2: 8:05 - 10:08 | J2: 11/6/2024 TUE | K2: 0.32638889 | L2: - | M2: 0.38680556 | N2: =M2-K2 -> 0.060416667 | O2: 201 | R2: 0.32638889 | S2: - | T2: 0.38680556 | U2: =IF(T2<>"",T2-R2,"") -> 0.060416667 | V2: 203 | Y2: 0.32638889 | Z2: - | AA2: 0.38680556 | AB2: =IF(AA2<>"",AA2-Y2,"") -> 0.060416667 | AC2: 49 | AF2: 0.32638889 | AG2: - | AH2: 0.41875 | AI2: =IF(AH2<>"",AH2-AF2,"") -> 0.092361111 | AJ2: 91 | AK2: 198 | AL2: 0.32638889 | AM2: - | AN2: 0.42222222 | AO2: =IF(AN2<>"",AN2-AL2,"") -> 0.095833333 | AP2: 211 | AQ2: (198) | AV2: =IF(AU2<>"",AU2-AS2,"") | BB2: =IF(BA2<>"",BA2-AY2,"") | BF2: 25 | BG2: 114 | BH2: 178 | BM2: 3 | BN2: =SUMIF($O$2:$O$41,BM2,$N$2:$N$41)+SUMIF($V$2:$V$41,BM2,$U$2:$U$41)+SUMIF($AC$2:$AC$41,BM2,$AB$2:$AB$41)+SUMIF($AJ$2:$AJ$41,BM2,$AI$2:$AI$41)+SUMIF($AP$2:$AP$41,BM2,$AO$2:$AO$41)+SUMIF($AW$2:$AW$41,BM2,$AV$2:$AV$41)+SUMIF($BC$2:$BC$41,BM2,$BB$2:$BB$41) -> 0.10277778 | BO2: =BN2*24 -> 2.4666667 | BQ2: =BM2 -> 3 | BR2: =SUMIF($P$2:$P$42,BQ2,$N$2:$N$41)+SUMIF($W$2:$W$42,BQ2,$U$2:$U$41)+SUMIF($AD$2:$AD$42,BQ2,$AB$2:$AB$41)+SUMIF($AK$2:$AK$42,BQ2,$AI$2:$AI$41)+SUMIF($AQ$2:$AQ$42,BQ2,$AO$2:$AO$41)+SUMIF($AX$2:$AX$42,BQ2,$AV$2:$AV$41)+SUMIF($BD$2:$BD$42,BQ2,$BB$2:$BB$41) -> 0 | BS2: =BR2*24 -> 0 | BU2: =BM2 -> 3 | BV2: =BO2+BS2 -> 2.4666667
D3: 9:50 - 10:44 | E3: 10:35 - 12:33 | F3: 10:40 - 13:44 | U3: =IF(T3<>"",T3-R3,"") | Y3: 0.39930556 | AA3: 0.44722222 | AB3: =IF(AA3<>"",AA3-Y3,"") -> 0.047916667 | AC3: 49 | AF3: 0.43055556 | AH3: 0.52291667 | AI3: =IF(AH3<>"",AH3-AF3,"") -> 0.092361111 | AJ3: 91 | AK3: 103 | AL3: 0.43402778 | AN3: 0.52083333 | AO3: =IF(AN3<>"",AN3-AL3,"") -> 0.086805556 | AP3: 153 | AQ3: (103) | AV3: =IF(AU3<>"",AU3-AS3,"") | BB3: =IF(BA3<>"",BA3-AY3,"") | BF3: 25 | BG3: 114 | BH3: 178 | BM3: 4 | BN3: =SUMIF($O$2:$O$41,BM3,$N$2:$N$41)+SUMIF($V$2:$V$41,BM3,$U$2:$U$41)+SUMIF($AC$2:$AC$41,BM3,$AB$2:$AB$41)+SUMIF($AJ$2:$AJ$41,BM3,$AI$2:$AI$41)+SUMIF($AP$2:$AP$41,BM3,$AO$2:$AO$41)+SUMIF($AW$2:$AW$41,BM3,$AV$2:$AV$41)+SUMIF($BC$2:$BC$41,BM3,$BB$2:$BB$41) -> 0 | BO3: =BN3*24 -> 0 | BQ3: =BM3 -> 4 | BR3: =SUMIF($P$2:$P$42,BQ3,$N$2:$N$41)+SUMIF($W$2:$W$42,BQ3,$U$2:$U$41)+SUMIF($AD$2:$AD$42,BQ3,$AB$2:$AB$41)+SUMIF($AK$2:$AK$42,BQ3,$AI$2:$AI$41)+SUMIF($AQ$2:$AQ$42,BQ3,$AO$2:$AO$41)+SUMIF($AX$2:$AX$42,BQ3,$AV$2:$AV$41)+SUMIF($BD$2:$BD$42,BQ3,$BB$2:$BB$41) -> 0 | BS3: =BR3*24 -> 0 | BU3: =BM3 -> 4 | BV3: =BO3+BS3 -> 0
N4: =IF(M4<>"",M4-K4,"") | U4: =IF(T4<>"",T4-R4,"") | AB4: =IF(AA4<>"",AA4-Y4,"") | AI4: =IF(AH4<>"",AH4-AF4,"") | AK4: IES2 | AL4: 0.52291667 | AN4: 0.57222222 | AO4: =IF(AN4<>"",AN4-AL4,"") -> 0.049305556 | AP4: IEC3 | AQ4: (IES2) | AV4: =IF(AU4<>"",AU4-AS4,"") | BB4: =IF(BA4<>"",BA4-AY4,"") | BF4: 25 | BG4: 114 | BH4: 178 | BM4: 5 | BN4: =SUMIF($O$2:$O$41,BM4,$N$2:$N$41)+SUMIF($V$2:$V$41,BM4,$U$2:$U$41)+SUMIF($AC$2:$AC$41,BM4,$AB$2:$AB$41)+SUMIF($AJ$2:$AJ$41,BM4,$AI$2:$AI$41)+SUMIF($AP$2:$AP$41,BM4,$AO$2:$AO$41)+SUMIF($AW$2:$AW$41,BM4,$AV$2:$AV$41)+SUMIF($BC$2:$BC$41,BM4,$BB$2:$BB$41) -> 0.15416667 | BO4: =BN4*24 -> 3.7 | BQ4: =BM4 -> 5 | BR4: =SUMIF($P$2:$P$42,BQ4,$N$2:$N$41)+SUMIF($W$2:$W$42,BQ4,$U$2:$U$41)+SUMIF($AD$2:$AD$42,BQ4,$AB$2:$AB$41)+SUMIF($AK$2:$AK$42,BQ4,$AI$2:$AI$41)+SUMIF($AQ$2:$AQ$42,BQ4,$AO$2:$AO$41)+SUMIF($AX$2:$AX$42,BQ4,$AV$2:$AV$41)+SUMIF($BD$2:$BD$42,BQ4,$BB$2:$BB$41) -> 0 | BS4: =BR4*24 -> 0 | BU4: =BM4 -> 5 | BV4: =BO4+BS4 -> 3.7
N5: =IF(M5<>"",M5-K5,"") | U5: =IF(T5<>"",T5-R5,"") | AB5: =IF(AA5<>"",AA5-Y5,"") | AI5: =IF(AH5<>"",AH5-AF5,"") | AO5: =IF(AN5<>"",AN5-AL5,"") | AV5: =IF(AU5<>"",AU5-AS5,"") | BB5: =IF(BA5<>"",BA5-AY5,"") | BF5: 25 | BG5: 114 | BH5: 178 | BM5: 20 | BN5: =SUMIF($O$2:$O$41,BM5,$N$2:$N$41)+SUMIF($V$2:$V$41,BM5,$U$2:$U$41)+SUMIF($AC$2:$AC$41,BM5,$AB$2:$AB$41)+SUMIF($AJ$2:$AJ$41,BM5,$AI$2:$AI$41)+SUMIF($AP$2:$AP$41,BM5,$AO$2:$AO$41)+SUMIF($AW$2:$AW$41,BM5,$AV$2:$AV$41)+SUMIF($BC$2:$BC$41,BM5,$BB$2:$BB$41) -> 0 | BO5: =BN5*24 -> 0 | BQ5: =BM5 -> 20 | BR5: =SUMIF($P$2:$P$42,BQ5,$N$2:$N$41)+SUMIF($W$2:$W$42,BQ5,$U$2:$U$41)+SUMIF($AD$2:$AD$42,BQ5,$AB$2:$AB$41)+SUMIF($AK$2:$AK$42,BQ5,$AI$2:$AI$41)+SUMIF($AQ$2:$AQ$42,BQ5,$AO$2:$AO$41)+SUMIF($AX$2:$AX$42,BQ5,$AV$2:$AV$41)+SUMIF($BD$2:$BD$42,BQ5,$BB$2:$BB$41) -> 0.125 | BS5: =BR5*24 -> 3 | BU5: =BM5 -> 20 | BV5: =BO5+BS5 -> 3
A6: 12/6/2024 WED | B6: 8:05 - 9:17 | C6: 8:05 - 8:41 | D6: 8:05 - 9:17 | E6: 8:05 - 9:45 | F6: 8:05 - 10:08 | J6: 12/6/2024 WED | K6: 0.32638889 | L6: - | M6: 0.38680556 | N6: =IF(M6<>"",M6-K6,"") -> 0.060416667 | O6: 211 | R6: 0.32638889 | T6: 0.36180556 | U6: =IF(T6<>"",T6-R6,"") -> 0.035416667 | V6: 218 | Y6: 0.32638889 | Z6: - | AA6: 0.38680556 | AB6: =IF(AA6<>"",AA6-Y6,"") -> 0.060416667 | AC6: 113 | AF6: 0.32638889 | AH6: 0.40625 | AI6: =IF(AH6<>"",AH6-AF6,"") -> 0.079861111 | AJ6: 138 | AK6: (TAP) | AL6: 0.32638889 | AM6: - | AN6: 0.42222222 | AO6: =IF(AN6<>"",AN6-AL6,"") -> 0.095833333 | AP6: 198 | AQ6: TAP | AV6: =IF(AU6<>"",AU6-AS6,"") | BB6: =IF(BA6<>"",BA6-AY6,"") | BE6: 49 | BF6: 25 | BG6: 114 | BH6: 178 | BI6: 117 | BJ6: 217 | BM6: 22 | BN6: =SUMIF($O$2:$O$41,BM6,$N$2:$N$41)+SUMIF($V$2:$V$41,BM6,$U$2:$U$41)+SUMIF($AC$2:$AC$41,BM6,$AB$2:$AB$41)+SUMIF($AJ$2:$AJ$41,BM6,$AI$2:$AI$41)+SUMIF($AP$2:$AP$41,BM6,$AO$2:$AO$41)+SUMIF($AW$2:$AW$41,BM6,$AV$2:$AV$41)+SUMIF($BC$2:$BC$41,BM6,$BB$2:$BB$41) -> 0.10833333 | BO6: =BN6*24 -> 2.6 | BQ6: =BM6 -> 22 | BR6: =SUMIF($P$2:$P$42,BQ6,$N$2:$N$41)+SUMIF($W$2:$W$42,BQ6,$U$2:$U$41)+SUMIF($AD$2:$AD$42,BQ6,$AB$2:$AB$41)+SUMIF($AK$2:$AK$42,BQ6,$AI$2:$AI$41)+SUMIF($AQ$2:$AQ$42,BQ6,$AO$2:$AO$41)+SUMIF($AX$2:$AX$42,BQ6,$AV$2:$AV$41)+SUMIF($BD$2:$BD$42,BQ6,$BB$2:$BB$41) -> 0 | BS6: =BR6*24 -> 0 | BU6: =BM6 -> 22 | BV6: =BO6+BS6 -> 2.6
B7: 9:50 - 11:02 | C7: 8:45 - 9:15 | D7: 9:50 - 10:44 | F7: 10:40 - 14:08 | K7: 0.39930556 | M7: 0.45972222 | N7: =IF(M7<>"",M7-K7,"") -> 0.060416667 | O7: 134 | R7: 0.36180556 | T7: 0.38541667 | U7: =IF(T7<>"",T7-R7,"") -> 0.023611111 | V7: 218 | Y7: 0.39930556 | AA7: 0.44722222 | AB7: =IF(AA7<>"",AA7-Y7,"") -> 0.047916667 | AC7: 113 | AI7: =IF(AH7<>"",AH7-AF7,"") | AL7: 0.43402778 | AM7: - | AN7: 0.52083333 | AO7: =IF(AN7<>"",AN7-AL7,"") -> 0.086805556 | AP7: 203 | AV7: =IF(AU7<>"",AU7-AS7,"") | BB7: =IF(BA7<>"",BA7-AY7,"") | BE7: 49 | BF7: 25 | BG7: 114 | BH7: 178 | BI7: 117 | BJ7: 217 | BM7: 25 | BN7: =SUMIF($O$2:$O$41,BM7,$N$2:$N$41)+SUMIF($V$2:$V$41,BM7,$U$2:$U$41)+SUMIF($AC$2:$AC$41,BM7,$AB$2:$AB$41)+SUMIF($AJ$2:$AJ$41,BM7,$AI$2:$AI$41)+SUMIF($AP$2:$AP$41,BM7,$AO$2:$AO$41)+SUMIF($AW$2:$AW$41,BM7,$AV$2:$AV$41)+SUMIF($BC$2:$BC$41,BM7,$BB$2:$BB$41) -> 0.19444444 | BO7: =BN7*24 -> 4.6666667 | BQ7: =BM7 -> 25 | BR7: =SUMIF($P$2:$P$42,BQ7,$N$2:$N$41)+SUMIF($W$2:$W$42,BQ7,$U$2:$U$41)+SUMIF($AD$2:$AD$42,BQ7,$AB$2:$AB$41)+SUMIF($AK$2:$AK$42,BQ7,$AI$2:$AI$41)+SUMIF($AQ$2:$AQ$42,BQ7,$AO$2:$AO$41)+SUMIF($AX$2:$AX$42,BQ7,$AV$2:$AV$41)+SUMIF($BD$2:$BD$42,BQ7,$BB$2:$BB$41) -> 0 | BS7: =BR7*24 -> 0 | BU7: =BM7 -> 25 | BV7: =BO7+BS7 -> 4.6666667
C8: 9:45 - 10:20 | N8: =IF(M8<>"",M8-K8,"") | R8: 0.40625 | T8: 0.43055556 | U8: =IF(T8<>"",T8-R8,"") -> 0.024305556 | V8: 218 | AB8: =IF(AA8<>"",AA8-Y8,"") | AI8: =IF(AH8<>"",AH8-AF8,"") | AL8: 0.52083333 | AM8: - | AN8: 0.58888889 | AO8: =IF(AN8<>"",AN8-AL8,"") -> 0.068055556 | AP8: IES2 | AV8: =IF(AU8<>"",AU8-AS8,"") | BB8: =IF(BA8<>"",BA8-AY8,"") | BE8: 49 | BF8: 25 | BG8: 114 | BH8: 178 | BI8: 117 | BJ8: 217 | BM8: 32 | BN8: =SUMIF($O$2:$O$41,BM8,$N$2:$N$41)+SUMIF($V$2:$V$41,BM8,$U$2:$U$41)+SUMIF($AC$2:$AC$41,BM8,$AB$2:$AB$41)+SUMIF($AJ$2:$AJ$41,BM8,$AI$2:$AI$41)+SUMIF($AP$2:$AP$41,BM8,$AO$2:$AO$41)+SUMIF($AW$2:$AW$41,BM8,$AV$2:$AV$41)+SUMIF($BC$2:$BC$41,BM8,$BB$2:$BB$41) -> 0 | BO8: =BN8*24 -> 0 | BQ8: =BM8 -> 32 | BR8: =SUMIF($P$2:$P$42,BQ8,$N$2:$N$41)+SUMIF($W$2:$W$42,BQ8,$U$2:$U$41)+SUMIF($AD$2:$AD$42,BQ8,$AB$2:$AB$41)+SUMIF($AK$2:$AK$42,BQ8,$AI$2:$AI$41)+SUMIF($AQ$2:$AQ$42,BQ8,$AO$2:$AO$41)+SUMIF($AX$2:$AX$42,BQ8,$AV$2:$AV$41)+SUMIF($BD$2:$BD$42,BQ8,$BB$2:$BB$41) -> 0 | BS8: =BR8*24 -> 0 | BU8: =BM8 -> 32 | BV8: =BO8+BS8 -> 0
N9: =IF(M9<>"",M9-K9,"") | U9: =IF(T9<>"",T9-R9,"") | AB9: =IF(AA9<>"",AA9-Y9,"") | AI9: =IF(AH9<>"",AH9-AF9,"") | AO9: =IF(AN9<>"",AN9-AL9,"") | AV9: =IF(AU9<>"",AU9-AS9,"") | BB9: =IF(BA9<>"",BA9-AY9,"") | BE9: 49 | BF9: 25 | BG9: 114 | BH9: 178 | BI9: 117 | BJ9: 217 | BM9: 37 | BN9: =SUMIF($O$2:$O$41,BM9,$N$2:$N$41)+SUMIF($V$2:$V$41,BM9,$U$2:$U$41)+SUMIF($AC$2:$AC$41,BM9,$AB$2:$AB$41)+SUMIF($AJ$2:$AJ$41,BM9,$AI$2:$AI$41)+SUMIF($AP$2:$AP$41,BM9,$AO$2:$AO$41)+SUMIF($AW$2:$AW$41,BM9,$AV$2:$AV$41)+SUMIF($BC$2:$BC$41,BM9,$BB$2:$BB$41) -> 0.059722222 | BO9: =BN9*24 -> 1.4333333 | BQ9: =BM9 -> 37 | BR9: =SUMIF($P$2:$P$42,BQ9,$N$2:$N$41)+SUMIF($W$2:$W$42,BQ9,$U$2:$U$41)+SUMIF($AD$2:$AD$42,BQ9,$AB$2:$AB$41)+SUMIF($AK$2:$AK$42,BQ9,$AI$2:$AI$41)+SUMIF($AQ$2:$AQ$42,BQ9,$AO$2:$AO$41)+SUMIF($AX$2:$AX$42,BQ9,$AV$2:$AV$41)+SUMIF($BD$2:$BD$42,BQ9,$BB$2:$BB$41) -> 0 | BS9: =BR9*24 -> 0 | BU9: =BM9 -> 37 | BV9: =BO9+BS9 -> 1.4333333
A10: 13/6/2024 THUR | B10: 8:05 - 9:35 | C10: 8:05 - 9:17 | D10: 8:05 - 9:17 | E10: 8:05 - 10:03 | F10: 8:05 - 10:50 | J10: 13/6/2024 THUR | K10: 0.32638889 | L10: - | M10: 0.39930556 | N10: =IF(M10<>"",M10-K10,"") -> 0.072916667 | O10: 78 | R10: 0.32638889 | S10: - | T10: 0.38680556 | U10: =IF(T10<>"",T10-R10,"") -> 0.060416667 | V10: 25 | Y10: 0.32638889 | Z10: - | AA10: 0.38680556 | AB10: =IF(AA10<>"",AA10-Y10,"") -> 0.060416667 | AC10: 22 | AF10: 0.32638889 | AG10: - | AH10: 0.41875 | AI10: =IF(AH10<>"",AH10-AF10,"") -> 0.092361111 | AJ10: 208 | AK10: 113 | AL10: 0.32638889 | AM10: - | AN10: 0.45138889 | AO10: =IF(AN10<>"",AN10-AL10,"") -> 0.125 | AP10: 91 | AQ10: （113） | AV10: =IF(AU10<>"",AU10-AS10,"") | BB10: =IF(BA10<>"",BA10-AY10,"") | BF10: 203 | BG10: 211 | BM10: 39 | BN10: =SUMIF($O$2:$O$41,BM10,$N$2:$N$41)+SUMIF($V$2:$V$41,BM10,$U$2:$U$41)+SUMIF($AC$2:$AC$41,BM10,$AB$2:$AB$41)+SUMIF($AJ$2:$AJ$41,BM10,$AI$2:$AI$41)+SUMIF($AP$2:$AP$41,BM10,$AO$2:$AO$41)+SUMIF($AW$2:$AW$41,BM10,$AV$2:$AV$41)+SUMIF($BC$2:$BC$41,BM10,$BB$2:$BB$41) -> 0 | BO10: =BN10*24 -> 0 | BQ10: =BM10 -> 39 | BR10: =SUMIF($P$2:$P$42,BQ10,$N$2:$N$41)+SUMIF($W$2:$W$42,BQ10,$U$2:$U$41)+SUMIF($AD$2:$AD$42,BQ10,$AB$2:$AB$41)+SUMIF($AK$2:$AK$42,BQ10,$AI$2:$AI$41)+SUMIF($AQ$2:$AQ$42,BQ10,$AO$2:$AO$41)+SUMIF($AX$2:$AX$42,BQ10,$AV$2:$AV$41)+SUMIF($BD$2:$BD$42,BQ10,$BB$2:$BB$41) -> 0 | BS10: =BR10*24 -> 0 | BU10: =BM10 -> 39 | BV10: =BO10+BS10 -> 0
D11: 9:50 - 11:02 | E11: 10:35 - 13:32 | F11: 11:20 - 14:05 | N11: =IF(M11<>"",M11-K11,"") | U11: =IF(T11<>"",T11-R11,"") | Y11: 0.39930556 | AA11: 0.45972222 | AB11: =IF(AA11<>"",AA11-Y11,"") -> 0.060416667 | AC11: 161 | AF11: 0.43055556 | AH11: 0.52083333 | AI11: =IF(AH11<>"",AH11-AF11,"") -> 0.090277778 | AJ11: 129 | AK11: IEC3 | AL11: 0.46180556 | AM11: - | AN11: 0.52083333 | AO11: =IF(AN11<>"",AN11-AL11,"") -> 0.059027778 | AP11: 114 | AQ11: （IEC3） | AV11: =IF(AU11<>"",AU11-AS11,"") | BB11: =IF(BA11<>"",BA11-AY11,"") | BF11: 203 | BG11: 211 | BM11: 49 | BN11: =SUMIF($O$2:$O$41,BM11,$N$2:$N$41)+SUMIF($V$2:$V$41,BM11,$U$2:$U$41)+SUMIF($AC$2:$AC$41,BM11,$AB$2:$AB$41)+SUMIF($AJ$2:$AJ$41,BM11,$AI$2:$AI$41)+SUMIF($AP$2:$AP$41,BM11,$AO$2:$AO$41)+SUMIF($AW$2:$AW$41,BM11,$AV$2:$AV$41)+SUMIF($BC$2:$BC$41,BM11,$BB$2:$BB$41) -> 0.16875 | BO11: =BN11*24 -> 4.05 | BQ11: =BM11 -> 49 | BR11: =SUMIF($P$2:$P$42,BQ11,$N$2:$N$41)+SUMIF($W$2:$W$42,BQ11,$U$2:$U$41)+SUMIF($AD$2:$AD$42,BQ11,$AB$2:$AB$41)+SUMIF($AK$2:$AK$42,BQ11,$AI$2:$AI$41)+SUMIF($AQ$2:$AQ$42,BQ11,$AO$2:$AO$41)+SUMIF($AX$2:$AX$42,BQ11,$AV$2:$AV$41)+SUMIF($BD$2:$BD$42,BQ11,$BB$2:$BB$41) -> 0 | BS11: =BR11*24 -> 0 | BU11: =BM11 -> 49 | BV11: =BO11+BS11 -> 4.05
N12: =IF(M12<>"",M12-K12,"") | U12: =IF(T12<>"",T12-R12,"") | AB12: =IF(AA12<>"",AA12-Y12,"") | AF12: 0.52083333 | AG12: - | AH12: 0.56388889 | AI12: =IF(AH12<>"",AH12-AF12,"") -> 0.043055556 | AJ12: IES2 | AK12: IEC3 | AL12: 0.52083333 | AM12: - | AN12: 0.58680556 | AO12: =IF(AN12<>"",AN12-AL12,"") -> 0.065972222 | AP12: PTC | AQ12: (IEC3) | AV12: =IF(AU12<>"",AU12-AS12,"") | BB12: =IF(BA12<>"",BA12-AY12,"") | BE12: 72 | BF12: 203 | BG12: 211 | BM12: 67 | BN12: =SUMIF($O$2:$O$41,BM12,$N$2:$N$41)+SUMIF($V$2:$V$41,BM12,$U$2:$U$41)+SUMIF($AC$2:$AC$41,BM12,$AB$2:$AB$41)+SUMIF($AJ$2:$AJ$41,BM12,$AI$2:$AI$41)+SUMIF($AP$2:$AP$41,BM12,$AO$2:$AO$41)+SUMIF($AW$2:$AW$41,BM12,$AV$2:$AV$41)+SUMIF($BC$2:$BC$41,BM12,$BB$2:$BB$41) -> 0 | BO12: =BN12*24 -> 0 | BQ12: =BM12 -> 67 | BR12: =SUMIF($P$2:$P$42,BQ12,$N$2:$N$41)+SUMIF($W$2:$W$42,BQ12,$U$2:$U$41)+SUMIF($AD$2:$AD$42,BQ12,$AB$2:$AB$41)+SUMIF($AK$2:$AK$42,BQ12,$AI$2:$AI$41)+SUMIF($AQ$2:$AQ$42,BQ12,$AO$2:$AO$41)+SUMIF($AX$2:$AX$42,BQ12,$AV$2:$AV$41)+SUMIF($BD$2:$BD$42,BQ12,$BB$2:$BB$41) -> 0 | BS12: =BR12*24 -> 0 | BU12: =BM12 -> 67 | BV12: =BO12+BS12 -> 0
N13: =IF(M13<>"",M13-K13,"") | U13: =IF(T13<>"",T13-R13,"") | AB13: =IF(AA13<>"",AA13-Y13,"") | AI13: =IF(AH13<>"",AH13-AF13,"") | AO13: =IF(AN13<>"",AN13-AL13,"") | AV13: =IF(AU13<>"",AU13-AS13,"") | BB13: =IF(BA13<>"",BA13-AY13,"") | BE13: 72 | BF13: 203 | BG13: 211 | BM13: 72 | BN13: =SUMIF($O$2:$O$41,BM13,$N$2:$N$41)+SUMIF($V$2:$V$41,BM13,$U$2:$U$41)+SUMIF($AC$2:$AC$41,BM13,$AB$2:$AB$41)+SUMIF($AJ$2:$AJ$41,BM13,$AI$2:$AI$41)+SUMIF($AP$2:$AP$41,BM13,$AO$2:$AO$41)+SUMIF($AW$2:$AW$41,BM13,$AV$2:$AV$41)+SUMIF($BC$2:$BC$41,BM13,$BB$2:$BB$41) -> 0 | BO13: =BN13*24 -> 0 | BQ13: =BM13 -> 72 | BR13: =SUMIF($P$2:$P$42,BQ13,$N$2:$N$41)+SUMIF($W$2:$W$42,BQ13,$U$2:$U$41)+SUMIF($AD$2:$AD$42,BQ13,$AB$2:$AB$41)+SUMIF($AK$2:$AK$42,BQ13,$AI$2:$AI$41)+SUMIF($AQ$2:$AQ$42,BQ13,$AO$2:$AO$41)+SUMIF($AX$2:$AX$42,BQ13,$AV$2:$AV$41)+SUMIF($BD$2:$BD$42,BQ13,$BB$2:$BB$41) -> 0 | BS13: =BR13*24 -> 0 | BU13: =BM13 -> 72 | BV13: =BO13+BS13 -> 0
A14: 14/6/2024 FRI | B14: 8:05 - 9:17 | C14: 8:05 - 9:17 | D14: 8:05 - 9:35 | E14: 8:05 - 10:03 | F14: 8:05 - 10:50 | G14: 8:15 - 12:57 (S4) | H14: 8:05 - 10:50 | J14: 14/6/2024 FRI | K14: 0.32638889 | L14: - | M14: 0.38680556 | N14: =IF(M14<>"",M14-K14,"") -> 0.060416667 | O14: 211 | R14: 0.32638889 | S14: - | T14: 0.38680556 | U14: =IF(T14<>"",T14-R14,"") -> 0.060416667 | V14: 114 | Y14: 0.32638889 | Z14: - | AA14: 0.39930556 | AB14: =IF(AA14<>"",AA14-Y14,"") -> 0.072916667 | AC14: 129 | AF14: 0.32638889 | AH14: 0.41875 | AI14: =IF(AH14<>"",AH14-AF14,"") -> 0.092361111 | AJ14: 91 | AK14: (TAP) | AL14: 0.32638889 | AM14: - | AN14: 0.45138889 | AO14: =IF(AN14<>"",AN14-AL14,"") -> 0.125 | AP14: 203 | AQ14: TAP | AS14: 0.32638889 | AT14: - | AU14: 0.45138889 | AV14: =IF(AU14<>"",AU14-AS14,"") -> 0.125 | AW14: 218 | AX14: 88 | BB14: =IF(BA14<>"",BA14-AY14,"") | BE14: 49 | BF14: 113 | BG14: 186 | BM14: 73 | BN14: =SUMIF($O$2:$O$41,BM14,$N$2:$N$41)+SUMIF($V$2:$V$41,BM14,$U$2:$U$41)+SUMIF($AC$2:$AC$41,BM14,$AB$2:$AB$41)+SUMIF($AJ$2:$AJ$41,BM14,$AI$2:$AI$41)+SUMIF($AP$2:$AP$41,BM14,$AO$2:$AO$41)+SUMIF($AW$2:$AW$41,BM14,$AV$2:$AV$41)+SUMIF($BC$2:$BC$41,BM14,$BB$2:$BB$41) -> 0 | BO14: =BN14*24 -> 0 | BQ14: =BM14 -> 73 | BR14: =SUMIF($P$2:$P$42,BQ14,$N$2:$N$41)+SUMIF($W$2:$W$42,BQ14,$U$2:$U$41)+SUMIF($AD$2:$AD$42,BQ14,$AB$2:$AB$41)+SUMIF($AK$2:$AK$42,BQ14,$AI$2:$AI$41)+SUMIF($AQ$2:$AQ$42,BQ14,$AO$2:$AO$41)+SUMIF($AX$2:$AX$42,BQ14,$AV$2:$AV$41)+SUMIF($BD$2:$BD$42,BQ14,$BB$2:$BB$41) -> 0 | BS14: =BR14*24 -> 0 | BU14: =BM14 -> 73 | BV14: =BO14+BS14 -> 0
B15: 9:50 - 11:02 | D15: 10:05 - 10:35 | G15: 8:15 - 12:57 (S5) | K15: 0.39930556 | M15: 0.45972222 | N15: =IF(M15<>"",M15-K15,"") -> 0.060416667 | O15: 211 | U15: =IF(T15<>"",T15-R15,"") | Y15: 0.40972222 | AA15: 0.44097222 | AB15: =IF(AA15<>"",AA15-Y15,"") -> 0.03125 | AC15: 129 | AI15: =IF(AH15<>"",AH15-AF15,"") | AO15: =IF(AN15<>"",AN15-AL15,"") | AV15: =IF(AU15<>"",AU15-AS15,"") | BB15: =IF(BA15<>"",BA15-AY15,"") | BE15: 49 | BF15: 113 | BG15: 186 | BM15: 76 | BN15: =SUMIF($O$2:$O$41,BM15,$N$2:$N$41)+SUMIF($V$2:$V$41,BM15,$U$2:$U$41)+SUMIF($AC$2:$AC$41,BM15,$AB$2:$AB$41)+SUMIF($AJ$2:$AJ$41,BM15,$AI$2:$AI$41)+SUMIF($AP$2:$AP$41,BM15,$AO$2:$AO$41)+SUMIF($AW$2:$AW$41,BM15,$AV$2:$AV$41)+SUMIF($BC$2:$BC$41,BM15,$BB$2:$BB$41) -> 0 | BO15: =BN15*24 -> 0 | BQ15: =BM15 -> 76 | BR15: =SUMIF($P$2:$P$42,BQ15,$N$2:$N$41)+SUMIF($W$2:$W$42,BQ15,$U$2:$U$41)+SUMIF($AD$2:$AD$42,BQ15,$AB$2:$AB$41)+SUMIF($AK$2:$AK$42,BQ15,$AI$2:$AI$41)+SUMIF($AQ$2:$AQ$42,BQ15,$AO$2:$AO$41)+SUMIF($AX$2:$AX$42,BQ15,$AV$2:$AV$41)+SUMIF($BD$2:$BD$42,BQ15,$BB$2:$BB$41) -> 0 | BS15: =BR15*24 -> 0 | BU15: =BM15 -> 76 | BV15: =BO15+BS15 -> 0
N16: =IF(M16<>"",M16-K16,"") | U16: =IF(T16<>"",T16-R16,"") | AB16: =IF(AA16<>"",AA16-Y16,"") | AI16: =IF(AH16<>"",AH16-AF16,"") | AO16: =IF(AN16<>"",AN16-AL16,"") | AV16: =IF(AU16<>"",AU16-AS16,"") | BB16: =IF(BA16<>"",BA16-AY16,"") | BE16: 49 | BF16: 113 | BG16: 186 | BM16: 78 | BN16: =SUMIF($O$2:$O$41,BM16,$N$2:$N$41)+SUMIF($V$2:$V$41,BM16,$U$2:$U$41)+SUMIF($AC$2:$AC$41,BM16,$AB$2:$AB$41)+SUMIF($AJ$2:$AJ$41,BM16,$AI$2:$AI$41)+SUMIF($AP$2:$AP$41,BM16,$AO$2:$AO$41)+SUMIF($AW$2:$AW$41,BM16,$AV$2:$AV$41)+SUMIF($BC$2:$BC$41,BM16,$BB$2:$BB$41) -> 0.072916667 | BO16: =BN16*24 -> 1.75 | BQ16: =BM16 -> 78 | BR16: =SUMIF($P$2:$P$42,BQ16,$N$2:$N$41)+SUMIF($W$2:$W$42,BQ16,$U$2:$U$41)+SUMIF($AD$2:$AD$42,BQ16,$AB$2:$AB$41)+SUMIF($AK$2:$AK$42,BQ16,$AI$2:$AI$41)+SUMIF($AQ$2:$AQ$42,BQ16,$AO$2:$AO$41)+SUMIF($AX$2:$AX$42,BQ16,$AV$2:$AV$41)+SUMIF($BD$2:$BD$42,BQ16,$BB$2:$BB$41) -> 0 | BS16: =BR16*24 -> 0 | BU16: =BM16 -> 78 | BV16: =BO16+BS16 -> 1.75
N17: =IF(M17<>"",M17-K17,"") | U17: =IF(T17<>"",T17-R17,"") | AB17: =IF(AA17<>"",AA17-Y17,"") | AI17: =IF(AH17<>"",AH17-AF17,"") | AO17: =IF(AN17<>"",AN17-AL17,"") | AV17: =IF(AU17<>"",AU17-AS17,"") | BB17: =IF(BA17<>"",BA17-AY17,"") | BE17: 49 | BF17: 113 | BG17: 186 | BM17: 84 | BN17: =SUMIF($O$2:$O$41,BM17,$N$2:$N$41)+SUMIF($V$2:$V$41,BM17,$U$2:$U$41)+SUMIF($AC$2:$AC$41,BM17,$AB$2:$AB$41)+SUMIF($AJ$2:$AJ$41,BM17,$AI$2:$AI$41)+SUMIF($AP$2:$AP$41,BM17,$AO$2:$AO$41)+SUMIF($AW$2:$AW$41,BM17,$AV$2:$AV$41)+SUMIF($BC$2:$BC$41,BM17,$BB$2:$BB$41) -> 0.125 | BO17: =BN17*24 -> 3 | BQ17: =BM17 -> 84 | BR17: =SUMIF($P$2:$P$42,BQ17,$N$2:$N$41)+SUMIF($W$2:$W$42,BQ17,$U$2:$U$41)+SUMIF($AD$2:$AD$42,BQ17,$AB$2:$AB$41)+SUMIF($AK$2:$AK$42,BQ17,$AI$2:$AI$41)+SUMIF($AQ$2:$AQ$42,BQ17,$AO$2:$AO$41)+SUMIF($AX$2:$AX$42,BQ17,$AV$2:$AV$41)+SUMIF($BD$2:$BD$42,BQ17,$BB$2:$BB$41) -> 0 | BS17: =BR17*24 -> 0 | BU17: =BM17 -> 84 | BV17: =BO17+BS17 -> 3
A18: 17/6/2024 MON | B18: 8:15 - 9:09 | C18: 8:15 - 9:45 | D18: 8:15 - 9:27 | E18: 8:15 - 9:27 | F18: 8:15 - 11:43 | J18: 17/6/2024 MON | K18: 0.33333333 | M18: 0.38125 | N18: =IF(M18<>"",M18-K18,"") -> 0.047916667 | O18: 22 | R18: 0.33333333 | T18: 0.40625 | U18: =IF(T18<>"",T18-R18,"") -> 0.072916667 | V18: 218 | Y18: 0.33333333 | AA18: 0.39375 | AB18: =IF(AA18<>"",AA18-Y18,"") -> 0.060416667 | AC18: 138 | AF18: 0.33333333 | AH18: 0.39375 | AI18: =IF(AH18<>"",AH18-AF18,"") -> 0.060416667 | AJ18: 5 | AK18: 147 | AL18: 0.33333333 | AN18: 0.48819444 | AO18: =IF(AN18<>"",AN18-AL18,"") -> 0.15486111 | AP18: 202 | AQ18: （147） | AV18: =IF(AU18<>"",AU18-AS18,"") | BB18: =IF(BA18<>"",BA18-AY18,"") | BM18: 85 | BN18: =SUMIF($O$2:$O$41,BM18,$N$2:$N$41)+SUMIF($V$2:$V$41,BM18,$U$2:$U$41)+SUMIF($AC$2:$AC$41,BM18,$AB$2:$AB$41)+SUMIF($AJ$2:$AJ$41,BM18,$AI$2:$AI$41)+SUMIF($AP$2:$AP$41,BM18,$AO$2:$AO$41)+SUMIF($AW$2:$AW$41,BM18,$AV$2:$AV$41)+SUMIF($BC$2:$BC$41,BM18,$BB$2:$BB$41) -> 0 | BO18: =BN18*24 -> 0 | BQ18: =BM18 -> 85 | BR18: =SUMIF($P$2:$P$42,BQ18,$N$2:$N$41)+SUMIF($W$2:$W$42,BQ18,$U$2:$U$41)+SUMIF($AD$2:$AD$42,BQ18,$AB$2:$AB$41)+SUMIF($AK$2:$AK$42,BQ18,$AI$2:$AI$41)+SUMIF($AQ$2:$AQ$42,BQ18,$AO$2:$AO$41)+SUMIF($AX$2:$AX$42,BQ18,$AV$2:$AV$41)+SUMIF($BD$2:$BD$42,BQ18,$BB$2:$BB$41) -> 0 | BS18: =BR18*24 -> 0 | BU18: =BM18 -> 85 | BV18: =BO18+BS18 -> 0
B19: 9:40 - 10:10 | C19: 10:15 - 10:45 | D19: 10:00 - 11:12 | E19: 10:00 - 11:58 | K19: 0.39236111 | M19: 0.42361111 | N19: =IF(M19<>"",M19-K19,"") -> 0.03125 | O19: 203 | R19: 0.41666667 | T19: 0.44791667 | U19: =IF(T19<>"",T19-R19,"") -> 0.03125 | V19: 218 | Y19: 0.40625 | AA19: 0.46666667 | AB19: =IF(AA19<>"",AA19-Y19,"") -> 0.060416667 | AC19: 138 | AF19: 0.40625 | AH19: 0.49861111 | AI19: =IF(AH19<>"",AH19-AF19,"") -> 0.092361111 | AJ19: 208 | AK19: IEC3 | AO19: =IF(AN19<>"",AN19-AL19,"") | AV19: =IF(AU19<>"",AU19-AS19,"") | BB19: =IF(BA19<>"",BA19-AY19,"") | BL19: CHECK | BM19: 86 | BN19: =SUMIF($O$2:$O$41,BM19,$N$2:$N$41)+SUMIF($V$2:$V$41,BM19,$U$2:$U$41)+SUMIF($AC$2:$AC$41,BM19,$AB$2:$AB$41)+SUMIF($AJ$2:$AJ$41,BM19,$AI$2:$AI$41)+SUMIF($AP$2:$AP$41,BM19,$AO$2:$AO$41)+SUMIF($AW$2:$AW$41,BM19,$AV$2:$AV$41)+SUMIF($BC$2:$BC$41,BM19,$BB$2:$BB$41) -> 0 | BO19: =BN19*24 -> 0 | BQ19: =BM19 -> 86 | BR19: =SUMIF($P$2:$P$42,BQ19,$N$2:$N$41)+SUMIF($W$2:$W$42,BQ19,$U$2:$U$41)+SUMIF($AD$2:$AD$42,BQ19,$AB$2:$AB$41)+SUMIF($AK$2:$AK$42,BQ19,$AI$2:$AI$41)+SUMIF($AQ$2:$AQ$42,BQ19,$AO$2:$AO$41)+SUMIF($AX$2:$AX$42,BQ19,$AV$2:$AV$41)+SUMIF($BD$2:$BD$42,BQ19,$BB$2:$BB$41) -> 0 | BS19: =BR19*24 -> 0 | BU19: =BM19 -> 86 | BV19: =BO19+BS19 -> 0
N20: =IF(M20<>"",M20-K20,"") | U20: =IF(T20<>"",T20-R20,"") | AB20: =IF(AA20<>"",AA20-Y20,"") | AI20: =IF(AH20<>"",AH20-AF20,"") | AO20: =IF(AN20<>"",AN20-AL20,"") | AV20: =IF(AU20<>"",AU20-AS20,"") | BB20: =IF(BA20<>"",BA20-AY20,"") | BE20: 141 | BL20: 202 | BM20: 90 | BN20: =SUMIF($O$2:$O$41,BM20,$N$2:$N$41)+SUMIF($V$2:$V$41,BM20,$U$2:$U$41)+SUMIF($AC$2:$AC$41,BM20,$AB$2:$AB$41)+SUMIF($AJ$2:$AJ$41,BM20,$AI$2:$AI$41)+SUMIF($AP$2:$AP$41,BM20,$AO$2:$AO$41)+SUMIF($AW$2:$AW$41,BM20,$AV$2:$AV$41)+SUMIF($BC$2:$BC$41,BM20,$BB$2:$BB$41) -> 0 | BO20: =BN20*24 -> 0 | BQ20: =BM20 -> 90 | BR20: =SUMIF($P$2:$P$42,BQ20,$N$2:$N$41)+SUMIF($W$2:$W$42,BQ20,$U$2:$U$41)+SUMIF($AD$2:$AD$42,BQ20,$AB$2:$AB$41)+SUMIF($AK$2:$AK$42,BQ20,$AI$2:$AI$41)+SUMIF($AQ$2:$AQ$42,BQ20,$AO$2:$AO$41)+SUMIF($AX$2:$AX$42,BQ20,$AV$2:$AV$41)+SUMIF($BD$2:$BD$42,BQ20,$BB$2:$BB$41) -> 0 | BS20: =BR20*24 -> 0 | BU20: =BM20 -> 90 | BV20: =BO20+BS20 -> 0
N21: =IF(M21<>"",M21-K21,"") | U21: =IF(T21<>"",T21-R21,"") | AB21: =IF(AA21<>"",AA21-Y21,"") | AI21: =IF(AH21<>"",AH21-AF21,"") | AO21: =IF(AN21<>"",AN21-AL21,"") | AV21: =IF(AU21<>"",AU21-AS21,"") | BB21: =IF(BA21<>"",BA21-AY21,"") | BE21: 141 | BM21: 91 | BN21: =SUMIF($O$2:$O$41,BM21,$N$2:$N$41)+SUMIF($V$2:$V$41,BM21,$U$2:$U$41)+SUMIF($AC$2:$AC$41,BM21,$AB$2:$AB$41)+SUMIF($AJ$2:$AJ$41,BM21,$AI$2:$AI$41)+SUMIF($AP$2:$AP$41,BM21,$AO$2:$AO$41)+SUMIF($AW$2:$AW$41,BM21,$AV$2:$AV$41)+SUMIF($BC$2:$BC$41,BM21,$BB$2:$BB$41) -> 0.52708333 | BO21: =BN21*24 -> 12.65 | BQ21: =BM21 -> 91 | BR21: =SUMIF($P$2:$P$42,BQ21,$N$2:$N$41)+SUMIF($W$2:$W$42,BQ21,$U$2:$U$41)+SUMIF($AD$2:$AD$42,BQ21,$AB$2:$AB$41)+SUMIF($AK$2:$AK$42,BQ21,$AI$2:$AI$41)+SUMIF($AQ$2:$AQ$42,BQ21,$AO$2:$AO$41)+SUMIF($AX$2:$AX$42,BQ21,$AV$2:$AV$41)+SUMIF($BD$2:$BD$42,BQ21,$BB$2:$BB$41) -> 0 | BS21: =BR21*24 -> 0 | BU21: =BM21 -> 91 | BV21: =BO21+BS21 -> 12.65
A22: 18/6/2024 TUE | B22: 8:05 - 9:17 | C22: 8:05 - 9:17 | D22: 8:05 - 9:17 | E22: 8:05 - 10:03 | F22: 8:05 - 10:50 | J22: 18/6/2024 TUE | K22: 0.32638889 | L22: - | M22: 0.38680556 | N22: =IF(M22<>"",M22-K22,"") -> 0.060416667 | O22: 3 | R22: 0.32638889 | S22: - | T22: 0.38680556 | U22: =IF(T22<>"",T22-R22,"") -> 0.060416667 | V22: 134 | Y22: 0.32638889 | AA22: 0.38680556 | AB22: =IF(AA22<>"",AA22-Y22,"") -> 0.060416667 | AC22: 218 | AF22: 0.32638889 | AH22: 0.41875 | AI22: =IF(AH22<>"",AH22-AF22,"") -> 0.092361111 | AJ22: 211 | AK22: (113) | AL22: 0.32638889 | AN22: 0.45138889 | AO22: =IF(AN22<>"",AN22-AL22,"") -> 0.125 | AP22: 84 | AQ22: 113 | AV22: =IF(AU22<>"",AU22-AS22,"") | BB22: =IF(BA22<>"",BA22-AY22,"") | BM22: 92 | BN22: =SUMIF($O$2:$O$41,BM22,$N$2:$N$41)+SUMIF($V$2:$V$41,BM22,$U$2:$U$41)+SUMIF($AC$2:$AC$41,BM22,$AB$2:$AB$41)+SUMIF($AJ$2:$AJ$41,BM22,$AI$2:$AI$41)+SUMIF($AP$2:$AP$41,BM22,$AO$2:$AO$41)+SUMIF($AW$2:$AW$41,BM22,$AV$2:$AV$41)+SUMIF($BC$2:$BC$41,BM22,$BB$2:$BB$41) -> 0 | BO22: =BN22*24 -> 0 | BQ22: =BM22 -> 92 | BR22: =SUMIF($P$2:$P$42,BQ22,$N$2:$N$41)+SUMIF($W$2:$W$42,BQ22,$U$2:$U$41)+SUMIF($AD$2:$AD$42,BQ22,$AB$2:$AB$41)+SUMIF($AK$2:$AK$42,BQ22,$AI$2:$AI$41)+SUMIF($AQ$2:$AQ$42,BQ22,$AO$2:$AO$41)+SUMIF($AX$2:$AX$42,BQ22,$AV$2:$AV$41)+SUMIF($BD$2:$BD$42,BQ22,$BB$2:$BB$41) -> 0 | BS22: =BR22*24 -> 0 | BU22: =BM22 -> 92 | BV22: =BO22+BS22 -> 0
B23: 9:50 - 10:26 | D23: 9:50 - 10:14 | K23: 0.39236111 | M23: 0.43472222 | N23: =IF(M23<>"",M23-K23,"") -> 0.042361111 | O23: 3 | U23: =IF(T23<>"",T23-R23,"") | Y23: 0.39930556 | AA23: 0.42638889 | AB23: =IF(AA23<>"",AA23-Y23,"") -> 0.027083333 | AC23: 218 | AI23: =IF(AH23<>"",AH23-AF23,"") | AO23: =IF(AN23<>"",AN23-AL23,"") | AV23: =IF(AU23<>"",AU23-AS23,"") | BB23: =IF(BA23<>"",BA23-AY23,"") | BM23: 102 | BN23: =SUMIF($O$2:$O$41,BM23,$N$2:$N$41)+SUMIF($V$2:$V$41,BM23,$U$2:$U$41)+SUMIF($AC$2:$AC$41,BM23,$AB$2:$AB$41)+SUMIF($AJ$2:$AJ$41,BM23,$AI$2:$AI$41)+SUMIF($AP$2:$AP$41,BM23,$AO$2:$AO$41)+SUMIF($AW$2:$AW$41,BM23,$AV$2:$AV$41)+SUMIF($BC$2:$BC$41,BM23,$BB$2:$BB$41) -> 0 | BO23: =BN23*24 -> 0 | BQ23: =BM23 -> 102 | BR23: =SUMIF($P$2:$P$42,BQ23,$N$2:$N$41)+SUMIF($W$2:$W$42,BQ23,$U$2:$U$41)+SUMIF($AD$2:$AD$42,BQ23,$AB$2:$AB$41)+SUMIF($AK$2:$AK$42,BQ23,$AI$2:$AI$41)+SUMIF($AQ$2:$AQ$42,BQ23,$AO$2:$AO$41)+SUMIF($AX$2:$AX$42,BQ23,$AV$2:$AV$41)+SUMIF($BD$2:$BD$42,BQ23,$BB$2:$BB$41) -> 0 | BS23: =BR23*24 -> 0 | BU23: =BM23 -> 102 | BV23: =BO23+BS23 -> 0
D24: 10:20 - 10:56 | N24: =IF(M24<>"",M24-K24,"") | U24: =IF(T24<>"",T24-R24,"") | Y24: 0.42638889 | AA24: 0.45555556 | AB24: =IF(AA24<>"",AA24-Y24,"") -> 0.029166667 | AC24: 218 | AI24: =IF(AH24<>"",AH24-AF24,"") | AO24: =IF(AN24<>"",AN24-AL24,"") | AV24: =IF(AU24<>"",AU24-AS24,"") | BB24: =IF(BA24<>"",BA24-AY24,"") | BE24: 141 | BF24: 22 | BM24: 103 | BN24: =SUMIF($O$2:$O$41,BM24,$N$2:$N$41)+SUMIF($V$2:$V$41,BM24,$U$2:$U$41)+SUMIF($AC$2:$AC$41,BM24,$AB$2:$AB$41)+SUMIF($AJ$2:$AJ$41,BM24,$AI$2:$AI$41)+SUMIF($AP$2:$AP$41,BM24,$AO$2:$AO$41)+SUMIF($AW$2:$AW$41,BM24,$AV$2:$AV$41)+SUMIF($BC$2:$BC$41,BM24,$BB$2:$BB$41) -> 0 | BO24: =BN24*24 -> 0 | BQ24: =BM24 -> 103 | BR24: =SUMIF($P$2:$P$42,BQ24,$N$2:$N$41)+SUMIF($W$2:$W$42,BQ24,$U$2:$U$41)+SUMIF($AD$2:$AD$42,BQ24,$AB$2:$AB$41)+SUMIF($AK$2:$AK$42,BQ24,$AI$2:$AI$41)+SUMIF($AQ$2:$AQ$42,BQ24,$AO$2:$AO$41)+SUMIF($AX$2:$AX$42,BQ24,$AV$2:$AV$41)+SUMIF($BD$2:$BD$42,BQ24,$BB$2:$BB$41) -> 0.24722222 | BS24: =BR24*24 -> 5.9333333 | BU24: =BM24 -> 103 | BV24: =BO24+BS24 -> 5.9333333
N25: =IF(M25<>"",M25-K25,"") | U25: =IF(T25<>"",T25-R25,"") | AB25: =IF(AA25<>"",AA25-Y25,"") | AI25: =IF(AH25<>"",AH25-AF25,"") | AO25: =IF(AN25<>"",AN25-AL25,"") | AV25: =IF(AU25<>"",AU25-AS25,"") | BB25: =IF(BA25<>"",BA25-AY25,"") | BE25: 141 | BF25: 22 | BM25: 112 | BN25: =SUMIF($O$2:$O$41,BM25,$N$2:$N$41)+SUMIF($V$2:$V$41,BM25,$U$2:$U$41)+SUMIF($AC$2:$AC$41,BM25,$AB$2:$AB$41)+SUMIF($AJ$2:$AJ$41,BM25,$AI$2:$AI$41)+SUMIF($AP$2:$AP$41,BM25,$AO$2:$AO$41)+SUMIF($AW$2:$AW$41,BM25,$AV$2:$AV$41)+SUMIF($BC$2:$BC$41,BM25,$BB$2:$BB$41) -> 0.125 | BO25: =BN25*24 -> 3 | BQ25: =BM25 -> 112 | BR25: =SUMIF($P$2:$P$42,BQ25,$N$2:$N$41)+SUMIF($W$2:$W$42,BQ25,$U$2:$U$41)+SUMIF($AD$2:$AD$42,BQ25,$AB$2:$AB$41)+SUMIF($AK$2:$AK$42,BQ25,$AI$2:$AI$41)+SUMIF($AQ$2:$AQ$42,BQ25,$AO$2:$AO$41)+SUMIF($AX$2:$AX$42,BQ25,$AV$2:$AV$41)+SUMIF($BD$2:$BD$42,BQ25,$BB$2:$BB$41) -> 0 | BS25: =BR25*24 -> 0 | BU25: =BM25 -> 112 | BV25: =BO25+BS25 -> 3
A26: 19/6/2024 S3 TSA WED | B26: Home Study | C26: 8:05 - 8:59 | D26: 8:45 - 10:15 | F26: 8:05 - 10:34 | J26: 19/6/2024 S3 TSA WED | N26: =IF(M26<>"",M26-K26,"") | R26: 0.32638889 | T26: 0.37430556 | U26: =IF(T26<>"",T26-R26,"") -> 0.047916667 | V26: 211 | Y26: 0.33333333 | AA26: 0.42708333 | AB26: =IF(AA26<>"",AA26-Y26,"") -> 0.09375 | AC26: 5 | AI26: =IF(AH26<>"",AH26-AF26,"") | AL26: 0.32638889 | AM26: - | AN26: 0.44027778 | AO26: =IF(AN26<>"",AN26-AL26,"") -> 0.11388889 | AP26: 214 | AQ26: 120 | AV26: =IF(AU26<>"",AU26-AS26,"") | BB26: =IF(BA26<>"",BA26-AY26,"") | BM26: 113 | BN26: =SUMIF($O$2:$O$41,BM26,$N$2:$N$41)+SUMIF($V$2:$V$41,BM26,$U$2:$U$41)+SUMIF($AC$2:$AC$41,BM26,$AB$2:$AB$41)+SUMIF($AJ$2:$AJ$41,BM26,$AI$2:$AI$41)+SUMIF($AP$2:$AP$41,BM26,$AO$2:$AO$41)+SUMIF($AW$2:$AW$41,BM26,$AV$2:$AV$41)+SUMIF($BC$2:$BC$41,BM26,$BB$2:$BB$41) -> 0.10833333 | BO26: =BN26*24 -> 2.6 | BQ26: =BM26 -> 113 | BR26: =SUMIF($P$2:$P$42,BQ26,$N$2:$N$41)+SUMIF($W$2:$W$42,BQ26,$U$2:$U$41)+SUMIF($AD$2:$AD$42,BQ26,$AB$2:$AB$41)+SUMIF($AK$2:$AK$42,BQ26,$AI$2:$AI$41)+SUMIF($AQ$2:$AQ$42,BQ26,$AO$2:$AO$41)+SUMIF($AX$2:$AX$42,BQ26,$AV$2:$AV$41)+SUMIF($BD$2:$BD$42,BQ26,$BB$2:$BB$41) -> 0.21736111 | BS26: =BR26*24 -> 5.2166667 | BU26: =BM26 -> 113 | BV26: =BO26+BS26 -> 7.8166667
C27: 9:30 - 10:24 | D27: 10:35 - 11:11 | N27: =IF(M27<>"",M27-K27,"") | R27: 0.38541667 | T27: 0.43333333 | U27: =IF(T27<>"",T27-R27,"") -> 0.047916667 | V27: 203 | Y27: 0.43055556 | AA27: 0.46597222 | AB27: =IF(AA27<>"",AA27-Y27,"") -> 0.035416667 | AC27: 114 | AI27: =IF(AH27<>"",AH27-AF27,"") | AO27: =IF(AN27<>"",AN27-AL27,"") | AV27: =IF(AU27<>"",AU27-AS27,"") | BB27: =IF(BA27<>"",BA27-AY27,"") | BM27: 114 | BN27: =SUMIF($O$2:$O$41,BM27,$N$2:$N$41)+SUMIF($V$2:$V$41,BM27,$U$2:$U$41)+SUMIF($AC$2:$AC$41,BM27,$AB$2:$AB$41)+SUMIF($AJ$2:$AJ$41,BM27,$AI$2:$AI$41)+SUMIF($AP$2:$AP$41,BM27,$AO$2:$AO$41)+SUMIF($AW$2:$AW$41,BM27,$AV$2:$AV$41)+SUMIF($BC$2:$BC$41,BM27,$BB$2:$BB$41) -> 0.48958333 | BO27: =BN27*24 -> 11.75 | BQ27: =BM27 -> 114 | BR27: =SUMIF($P$2:$P$42,BQ27,$N$2:$N$41)+SUMIF($W$2:$W$42,BQ27,$U$2:$U$41)+SUMIF($AD$2:$AD$42,BQ27,$AB$2:$AB$41)+SUMIF($AK$2:$AK$42,BQ27,$AI$2:$AI$41)+SUMIF($AQ$2:$AQ$42,BQ27,$AO$2:$AO$41)+SUMIF($AX$2:$AX$42,BQ27,$AV$2:$AV$41)+SUMIF($BD$2:$BD$42,BQ27,$BB$2:$BB$41) -> 0 | BS27: =BR27*24 -> 0 | BU27: =BM27 -> 114 | BV27: =BO27+BS27 -> 11.75
D28: 11:30 - 11:45 | N28: =IF(M28<>"",M28-K28,"") | U28: =IF(T28<>"",T28-R28,"") | Y28: 0.46875 | AA28: 0.48958333 | AB28: =IF(AA28<>"",AA28-Y28,"") -> 0.020833333 | AC28: 114 | AI28: =IF(AH28<>"",AH28-AF28,"") | AO28: =IF(AN28<>"",AN28-AL28,"") | AV28: =IF(AU28<>"",AU28-AS28,"") | BB28: =IF(BA28<>"",BA28-AY28,"") | BM28: 117 | BN28: =SUMIF($O$2:$O$41,BM28,$N$2:$N$41)+SUMIF($V$2:$V$41,BM28,$U$2:$U$41)+SUMIF($AC$2:$AC$41,BM28,$AB$2:$AB$41)+SUMIF($AJ$2:$AJ$41,BM28,$AI$2:$AI$41)+SUMIF($AP$2:$AP$41,BM28,$AO$2:$AO$41)+SUMIF($AW$2:$AW$41,BM28,$AV$2:$AV$41)+SUMIF($BC$2:$BC$41,BM28,$BB$2:$BB$41) -> 0 | BO28: =BN28*24 -> 0 | BQ28: =BM28 -> 117 | BR28: =SUMIF($P$2:$P$42,BQ28,$N$2:$N$41)+SUMIF($W$2:$W$42,BQ28,$U$2:$U$41)+SUMIF($AD$2:$AD$42,BQ28,$AB$2:$AB$41)+SUMIF($AK$2:$AK$42,BQ28,$AI$2:$AI$41)+SUMIF($AQ$2:$AQ$42,BQ28,$AO$2:$AO$41)+SUMIF($AX$2:$AX$42,BQ28,$AV$2:$AV$41)+SUMIF($BD$2:$BD$42,BQ28,$BB$2:$BB$41) -> 0 | BS28: =BR28*24 -> 0 | BU28: =BM28 -> 117 | BV28: =BO28+BS28 -> 0
D29: 11:50 - 12:10 | N29: =IF(M29<>"",M29-K29,"") | U29: =IF(T29<>"",T29-R29,"") | Y29: 0.48958333 | AA29: 0.50694444 | AB29: =IF(AA29<>"",AA29-Y29,"") -> 0.017361111 | AC29: 114 | AI29: =IF(AH29<>"",AH29-AF29,"") | AO29: =IF(AN29<>"",AN29-AL29,"") | AV29: =IF(AU29<>"",AU29-AS29,"") | BB29: =IF(BA29<>"",BA29-AY29,"") | BM29: 120 | BN29: =SUMIF($O$2:$O$41,BM29,$N$2:$N$41)+SUMIF($V$2:$V$41,BM29,$U$2:$U$41)+SUMIF($AC$2:$AC$41,BM29,$AB$2:$AB$41)+SUMIF($AJ$2:$AJ$41,BM29,$AI$2:$AI$41)+SUMIF($AP$2:$AP$41,BM29,$AO$2:$AO$41)+SUMIF($AW$2:$AW$41,BM29,$AV$2:$AV$41)+SUMIF($BC$2:$BC$41,BM29,$BB$2:$BB$41) -> 0 | BO29: =BN29*24 -> 0 | BQ29: =BM29 -> 120 | BR29: =SUMIF($P$2:$P$42,BQ29,$N$2:$N$41)+SUMIF($W$2:$W$42,BQ29,$U$2:$U$41)+SUMIF($AD$2:$AD$42,BQ29,$AB$2:$AB$41)+SUMIF($AK$2:$AK$42,BQ29,$AI$2:$AI$41)+SUMIF($AQ$2:$AQ$42,BQ29,$AO$2:$AO$41)+SUMIF($AX$2:$AX$42,BQ29,$AV$2:$AV$41)+SUMIF($BD$2:$BD$42,BQ29,$BB$2:$BB$41) -> 0.11388889 | BS29: =BR29*24 -> 2.7333333 | BU29: =BM29 -> 120 | BV29: =BO29+BS29 -> 2.7333333
A30: 20/6/2024 S3 TSA THUR | B30: 8:05 - 8:40 | C30: Home Study | D30: 8:45 - 9:33 | E30: 8:05 - 10:03 | F30: 8:05 - 11:33 | J30: 20/6/2024 S3 TSA THUR | K30: 0.32638889 | M30: 0.36111111 | N30: =IF(M30<>"",M30-K30,"") -> 0.034722222 | O30: 134 | U30: =IF(T30<>"",T30-R30,"") | Y30: 0.33333333 | AA30: 0.39791667 | AB30: =IF(AA30<>"",AA30-Y30,"") -> 0.064583333 | AC30: 25 | AF30: 0.32638889 | AH30: 0.41875 | AI30: =IF(AH30<>"",AH30-AF30,"") -> 0.092361111 | AJ30: 129 | AK30: (103) | AL30: 0.32638889 | AN30: 0.48125 | AO30: =IF(AN30<>"",AN30-AL30,"") -> 0.15486111 | AP30: 114 | AQ30: 103 | AV30: =IF(AU30<>"",AU30-AS30,"") | BB30: =IF(BA30<>"",BA30-AY30,"") | BF30: 73 | BG30: 91 | BI30: 137 | BM30: 128 | BN30: =SUMIF($O$2:$O$41,BM30,$N$2:$N$41)+SUMIF($V$2:$V$41,BM30,$U$2:$U$41)+SUMIF($AC$2:$AC$41,BM30,$AB$2:$AB$41)+SUMIF($AJ$2:$AJ$41,BM30,$AI$2:$AI$41)+SUMIF($AP$2:$AP$41,BM30,$AO$2:$AO$41)+SUMIF($AW$2:$AW$41,BM30,$AV$2:$AV$41)+SUMIF($BC$2:$BC$41,BM30,$BB$2:$BB$41) -> 0 | BO30: =BN30*24 -> 0 | BQ30: =BM30 -> 128 | BR30: =SUMIF($P$2:$P$42,BQ30,$N$2:$N$41)+SUMIF($W$2:$W$42,BQ30,$U$2:$U$41)+SUMIF($AD$2:$AD$42,BQ30,$AB$2:$AB$41)+SUMIF($AK$2:$AK$42,BQ30,$AI$2:$AI$41)+SUMIF($AQ$2:$AQ$42,BQ30,$AO$2:$AO$41)+SUMIF($AX$2:$AX$42,BQ30,$AV$2:$AV$41)+SUMIF($BD$2:$BD$42,BQ30,$BB$2:$BB$41) -> 0 | BS30: =BR30*24 -> 0 | BU30: =BM30 -> 128 | BV30: =BO30+BS30 -> 0
B31: 8:45 - 9:09 | D31: 9:55 - 10:37 | K31: 0.36111111 | M31: 0.38125 | N31: =IF(M31<>"",M31-K31,"") -> 0.020138889 | O31: 134 | U31: =IF(T31<>"",T31-R31,"") | Y31: 0.40277778 | AA31: 0.44236111 | AB31: =IF(AA31<>"",AA31-Y31,"") -> 0.039583333 | AC31: 25 | AI31: =IF(AH31<>"",AH31-AF31,"") | AO31: =IF(AN31<>"",AN31-AL31,"") | AV31: =IF(AU31<>"",AU31-AS31,"") | BB31: =IF(BA31<>"",BA31-AY31,"") | BF31: 73 | BG31: 91 | BI31: 137 | BM31: 129 | BN31: =SUMIF($O$2:$O$41,BM31,$N$2:$N$41)+SUMIF($V$2:$V$41,BM31,$U$2:$U$41)+SUMIF($AC$2:$AC$41,BM31,$AB$2:$AB$41)+SUMIF($AJ$2:$AJ$41,BM31,$AI$2:$AI$41)+SUMIF($AP$2:$AP$41,BM31,$AO$2:$AO$41)+SUMIF($AW$2:$AW$41,BM31,$AV$2:$AV$41)+SUMIF($BC$2:$BC$41,BM31,$BB$2:$BB$41) -> 0.28680556 | BO31: =BN31*24 -> 6.8833333 | BQ31: =BM31 -> 129 | BR31: =SUMIF($P$2:$P$42,BQ31,$N$2:$N$41)+SUMIF($W$2:$W$42,BQ31,$U$2:$U$41)+SUMIF($AD$2:$AD$42,BQ31,$AB$2:$AB$41)+SUMIF($AK$2:$AK$42,BQ31,$AI$2:$AI$41)+SUMIF($AQ$2:$AQ$42,BQ31,$AO$2:$AO$41)+SUMIF($AX$2:$AX$42,BQ31,$AV$2:$AV$41)+SUMIF($BD$2:$BD$42,BQ31,$BB$2:$BB$41) -> 0 | BS31: =BR31*24 -> 0 | BU31: =BM31 -> 129 | BV31: =BO31+BS31 -> 6.8833333
D32: 10:45 - 11:20 | N32: =IF(M32<>"",M32-K32,"") | U32: =IF(T32<>"",T32-R32,"") | Y32: 0.44236111 | AA32: 0.47222222 | AB32: =IF(AA32<>"",AA32-Y32,"") -> 0.029861111 | AC32: 25 | AI32: =IF(AH32<>"",AH32-AF32,"") | AO32: =IF(AN32<>"",AN32-AL32,"") | AV32: =IF(AU32<>"",AU32-AS32,"") | BB32: =IF(BA32<>"",BA32-AY32,"") | BE32: 5 | BF32: 73 | BG32: 91 | BH32: 141 | BI32: 137 | BM32: 134 | BN32: =SUMIF($O$2:$O$41,BM32,$N$2:$N$41)+SUMIF($V$2:$V$41,BM32,$U$2:$U$41)+SUMIF($AC$2:$AC$41,BM32,$AB$2:$AB$41)+SUMIF($AJ$2:$AJ$41,BM32,$AI$2:$AI$41)+SUMIF($AP$2:$AP$41,BM32,$AO$2:$AO$41)+SUMIF($AW$2:$AW$41,BM32,$AV$2:$AV$41)+SUMIF($BC$2:$BC$41,BM32,$BB$2:$BB$41) -> 0.17569444 | BO32: =BN32*24 -> 4.2166667 | BQ32: =BM32 -> 134 | BR32: =SUMIF($P$2:$P$42,BQ32,$N$2:$N$41)+SUMIF($W$2:$W$42,BQ32,$U$2:$U$41)+SUMIF($AD$2:$AD$42,BQ32,$AB$2:$AB$41)+SUMIF($AK$2:$AK$42,BQ32,$AI$2:$AI$41)+SUMIF($AQ$2:$AQ$42,BQ32,$AO$2:$AO$41)+SUMIF($AX$2:$AX$42,BQ32,$AV$2:$AV$41)+SUMIF($BD$2:$BD$42,BQ32,$BB$2:$BB$41) -> 0 | BS32: =BR32*24 -> 0 | BU32: =BM32 -> 134 | BV32: =BO32+BS32 -> 4.2166667
